[2024-07-22 13:09:32,690] Chirags-Macbook/INFO/locust.main: Run time limit set to 20 seconds
[2024-07-22 13:09:32,691] Chirags-Macbook/INFO/locust.main: Starting Locust 2.28.0
[2024-07-22 13:09:32,691] Chirags-Macbook/INFO/locust.runners: Ramping to 100 users at a rate of 1.00 per second
[2024-07-22 13:09:52,202] Chirags-Macbook/INFO/locust.main: --run-time limit reached, shutting down
[2024-07-22 13:09:52,272] Chirags-Macbook/INFO/locust.main: writing html report to file: repo.html
[2024-07-22 13:09:52,354] Chirags-Macbook/INFO/locust.main: Shutting down (exit code 0)
[2024-07-22 13:14:30,987] Chirags-Macbook/INFO/locust.main: Run time limit set to 20 seconds
[2024-07-22 13:14:30,988] Chirags-Macbook/INFO/locust.main: Starting Locust 2.28.0
[2024-07-22 13:14:30,988] Chirags-Macbook/INFO/locust.runners: Ramping to 100 users at a rate of 1.00 per second
[2024-07-22 13:14:50,476] Chirags-Macbook/INFO/locust.main: --run-time limit reached, shutting down
[2024-07-22 13:14:50,550] Chirags-Macbook/INFO/locust.main: writing html report to file: repo.html
[2024-07-22 13:14:50,629] Chirags-Macbook/INFO/locust.main: Shutting down (exit code 1)
[2024-07-22 13:17:40,412] Chirags-Macbook/INFO/locust.main: Run time limit set to 20 seconds
[2024-07-22 13:17:40,412] Chirags-Macbook/INFO/locust.main: Starting Locust 2.28.0
[2024-07-22 13:17:40,413] Chirags-Macbook/INFO/locust.runners: Ramping to 100 users at a rate of 1.00 per second
[2024-07-22 13:17:59,931] Chirags-Macbook/INFO/locust.main: --run-time limit reached, shutting down
[2024-07-22 13:18:00,016] Chirags-Macbook/INFO/locust.main: writing html report to file: repo.html
[2024-07-22 13:18:00,099] Chirags-Macbook/ERROR/root: Uncaught exception in event handler: 
Traceback (most recent call last):
  File "/Library/Frameworks/Python.framework/Versions/3.12/lib/python3.12/site-packages/locust/event.py", line 47, in fire
    handler(**kwargs)
  File "/Users/chiragkhanduja/PycharmProjects/Hudle_Load/new_partner.py", line 155, in on_quitting
    save_to_excel(df, 'response.xlsx')
  File "/Users/chiragkhanduja/PycharmProjects/Hudle_Load/new_partner.py", line 144, in save_to_excel
    format = workbook.add_format({'text_wrap': True, 'valign': 'top', 'border': 1})
             ^^^^^^^^^^^^^^^^^^^
AttributeError: 'Workbook' object has no attribute 'add_format'

[2024-07-22 13:18:00,100] Chirags-Macbook/INFO/locust.main: Shutting down (exit code 1)
[2024-07-22 13:28:54,732] Chirags-Macbook/INFO/locust.main: Run time limit set to 10 seconds
[2024-07-22 13:28:54,733] Chirags-Macbook/INFO/locust.main: Starting Locust 2.28.0
[2024-07-22 13:28:54,733] Chirags-Macbook/INFO/locust.runners: Ramping to 100 users at a rate of 1.00 per second
[2024-07-22 13:28:55,892] Chirags-Macbook/ERROR/locust.user.task: 'Response' object has no attribute 'created_at'
Traceback (most recent call last):
  File "/Library/Frameworks/Python.framework/Versions/3.12/lib/python3.12/site-packages/locust/user/task.py", line 340, in run
    self.execute_next_task()
  File "/Library/Frameworks/Python.framework/Versions/3.12/lib/python3.12/site-packages/locust/user/task.py", line 373, in execute_next_task
    self.execute_task(self._task_queue.popleft())
  File "/Library/Frameworks/Python.framework/Versions/3.12/lib/python3.12/site-packages/locust/user/task.py", line 490, in execute_task
    task(self.user)
  File "/Users/chiragkhanduja/PycharmProjects/Hudle_Load/new_partner.py", line 113, in post_data
    created_at = response.created_at
                 ^^^^^^^^^^^^^^^^^^^
AttributeError: 'Response' object has no attribute 'created_at'

[2024-07-22 13:28:57,243] Chirags-Macbook/ERROR/locust.user.task: 'Response' object has no attribute 'created_at'
Traceback (most recent call last):
  File "/Library/Frameworks/Python.framework/Versions/3.12/lib/python3.12/site-packages/locust/user/task.py", line 340, in run
    self.execute_next_task()
  File "/Library/Frameworks/Python.framework/Versions/3.12/lib/python3.12/site-packages/locust/user/task.py", line 373, in execute_next_task
    self.execute_task(self._task_queue.popleft())
  File "/Library/Frameworks/Python.framework/Versions/3.12/lib/python3.12/site-packages/locust/user/task.py", line 490, in execute_task
    task(self.user)
  File "/Users/chiragkhanduja/PycharmProjects/Hudle_Load/new_partner.py", line 113, in post_data
    created_at = response.created_at
                 ^^^^^^^^^^^^^^^^^^^
AttributeError: 'Response' object has no attribute 'created_at'

[2024-07-22 13:28:57,995] Chirags-Macbook/ERROR/locust.user.task: 'Response' object has no attribute 'created_at'
Traceback (most recent call last):
  File "/Library/Frameworks/Python.framework/Versions/3.12/lib/python3.12/site-packages/locust/user/task.py", line 340, in run
    self.execute_next_task()
  File "/Library/Frameworks/Python.framework/Versions/3.12/lib/python3.12/site-packages/locust/user/task.py", line 373, in execute_next_task
    self.execute_task(self._task_queue.popleft())
  File "/Library/Frameworks/Python.framework/Versions/3.12/lib/python3.12/site-packages/locust/user/task.py", line 490, in execute_task
    task(self.user)
  File "/Users/chiragkhanduja/PycharmProjects/Hudle_Load/new_partner.py", line 113, in post_data
    created_at = response.created_at
                 ^^^^^^^^^^^^^^^^^^^
AttributeError: 'Response' object has no attribute 'created_at'

[2024-07-22 13:28:57,996] Chirags-Macbook/ERROR/locust.user.task: 'Response' object has no attribute 'created_at'
Traceback (most recent call last):
  File "/Library/Frameworks/Python.framework/Versions/3.12/lib/python3.12/site-packages/locust/user/task.py", line 340, in run
    self.execute_next_task()
  File "/Library/Frameworks/Python.framework/Versions/3.12/lib/python3.12/site-packages/locust/user/task.py", line 373, in execute_next_task
    self.execute_task(self._task_queue.popleft())
  File "/Library/Frameworks/Python.framework/Versions/3.12/lib/python3.12/site-packages/locust/user/task.py", line 490, in execute_task
    task(self.user)
  File "/Users/chiragkhanduja/PycharmProjects/Hudle_Load/new_partner.py", line 113, in post_data
    created_at = response.created_at
                 ^^^^^^^^^^^^^^^^^^^
AttributeError: 'Response' object has no attribute 'created_at'

[2024-07-22 13:28:58,841] Chirags-Macbook/ERROR/locust.user.task: 'Response' object has no attribute 'created_at'
Traceback (most recent call last):
  File "/Library/Frameworks/Python.framework/Versions/3.12/lib/python3.12/site-packages/locust/user/task.py", line 340, in run
    self.execute_next_task()
  File "/Library/Frameworks/Python.framework/Versions/3.12/lib/python3.12/site-packages/locust/user/task.py", line 373, in execute_next_task
    self.execute_task(self._task_queue.popleft())
  File "/Library/Frameworks/Python.framework/Versions/3.12/lib/python3.12/site-packages/locust/user/task.py", line 490, in execute_task
    task(self.user)
  File "/Users/chiragkhanduja/PycharmProjects/Hudle_Load/new_partner.py", line 113, in post_data
    created_at = response.created_at
                 ^^^^^^^^^^^^^^^^^^^
AttributeError: 'Response' object has no attribute 'created_at'

[2024-07-22 13:28:58,857] Chirags-Macbook/ERROR/locust.user.task: 'Response' object has no attribute 'created_at'
Traceback (most recent call last):
  File "/Library/Frameworks/Python.framework/Versions/3.12/lib/python3.12/site-packages/locust/user/task.py", line 340, in run
    self.execute_next_task()
  File "/Library/Frameworks/Python.framework/Versions/3.12/lib/python3.12/site-packages/locust/user/task.py", line 373, in execute_next_task
    self.execute_task(self._task_queue.popleft())
  File "/Library/Frameworks/Python.framework/Versions/3.12/lib/python3.12/site-packages/locust/user/task.py", line 490, in execute_task
    task(self.user)
  File "/Users/chiragkhanduja/PycharmProjects/Hudle_Load/new_partner.py", line 113, in post_data
    created_at = response.created_at
                 ^^^^^^^^^^^^^^^^^^^
AttributeError: 'Response' object has no attribute 'created_at'

[2024-07-22 13:29:00,397] Chirags-Macbook/ERROR/locust.user.task: 'Response' object has no attribute 'created_at'
Traceback (most recent call last):
  File "/Library/Frameworks/Python.framework/Versions/3.12/lib/python3.12/site-packages/locust/user/task.py", line 340, in run
    self.execute_next_task()
  File "/Library/Frameworks/Python.framework/Versions/3.12/lib/python3.12/site-packages/locust/user/task.py", line 373, in execute_next_task
    self.execute_task(self._task_queue.popleft())
  File "/Library/Frameworks/Python.framework/Versions/3.12/lib/python3.12/site-packages/locust/user/task.py", line 490, in execute_task
    task(self.user)
  File "/Users/chiragkhanduja/PycharmProjects/Hudle_Load/new_partner.py", line 113, in post_data
    created_at = response.created_at
                 ^^^^^^^^^^^^^^^^^^^
AttributeError: 'Response' object has no attribute 'created_at'

[2024-07-22 13:29:00,652] Chirags-Macbook/ERROR/locust.user.task: 'Response' object has no attribute 'created_at'
Traceback (most recent call last):
  File "/Library/Frameworks/Python.framework/Versions/3.12/lib/python3.12/site-packages/locust/user/task.py", line 340, in run
    self.execute_next_task()
  File "/Library/Frameworks/Python.framework/Versions/3.12/lib/python3.12/site-packages/locust/user/task.py", line 373, in execute_next_task
    self.execute_task(self._task_queue.popleft())
  File "/Library/Frameworks/Python.framework/Versions/3.12/lib/python3.12/site-packages/locust/user/task.py", line 490, in execute_task
    task(self.user)
  File "/Users/chiragkhanduja/PycharmProjects/Hudle_Load/new_partner.py", line 113, in post_data
    created_at = response.created_at
                 ^^^^^^^^^^^^^^^^^^^
AttributeError: 'Response' object has no attribute 'created_at'

[2024-07-22 13:29:01,106] Chirags-Macbook/ERROR/locust.user.task: 'Response' object has no attribute 'created_at'
Traceback (most recent call last):
  File "/Library/Frameworks/Python.framework/Versions/3.12/lib/python3.12/site-packages/locust/user/task.py", line 340, in run
    self.execute_next_task()
  File "/Library/Frameworks/Python.framework/Versions/3.12/lib/python3.12/site-packages/locust/user/task.py", line 373, in execute_next_task
    self.execute_task(self._task_queue.popleft())
  File "/Library/Frameworks/Python.framework/Versions/3.12/lib/python3.12/site-packages/locust/user/task.py", line 490, in execute_task
    task(self.user)
  File "/Users/chiragkhanduja/PycharmProjects/Hudle_Load/new_partner.py", line 113, in post_data
    created_at = response.created_at
                 ^^^^^^^^^^^^^^^^^^^
AttributeError: 'Response' object has no attribute 'created_at'

[2024-07-22 13:29:01,108] Chirags-Macbook/ERROR/locust.user.task: 'Response' object has no attribute 'created_at'
Traceback (most recent call last):
  File "/Library/Frameworks/Python.framework/Versions/3.12/lib/python3.12/site-packages/locust/user/task.py", line 340, in run
    self.execute_next_task()
  File "/Library/Frameworks/Python.framework/Versions/3.12/lib/python3.12/site-packages/locust/user/task.py", line 373, in execute_next_task
    self.execute_task(self._task_queue.popleft())
  File "/Library/Frameworks/Python.framework/Versions/3.12/lib/python3.12/site-packages/locust/user/task.py", line 490, in execute_task
    task(self.user)
  File "/Users/chiragkhanduja/PycharmProjects/Hudle_Load/new_partner.py", line 113, in post_data
    created_at = response.created_at
                 ^^^^^^^^^^^^^^^^^^^
AttributeError: 'Response' object has no attribute 'created_at'

[2024-07-22 13:29:01,109] Chirags-Macbook/ERROR/locust.user.task: 'Response' object has no attribute 'created_at'
Traceback (most recent call last):
  File "/Library/Frameworks/Python.framework/Versions/3.12/lib/python3.12/site-packages/locust/user/task.py", line 340, in run
    self.execute_next_task()
  File "/Library/Frameworks/Python.framework/Versions/3.12/lib/python3.12/site-packages/locust/user/task.py", line 373, in execute_next_task
    self.execute_task(self._task_queue.popleft())
  File "/Library/Frameworks/Python.framework/Versions/3.12/lib/python3.12/site-packages/locust/user/task.py", line 490, in execute_task
    task(self.user)
  File "/Users/chiragkhanduja/PycharmProjects/Hudle_Load/new_partner.py", line 113, in post_data
    created_at = response.created_at
                 ^^^^^^^^^^^^^^^^^^^
AttributeError: 'Response' object has no attribute 'created_at'

[2024-07-22 13:29:01,111] Chirags-Macbook/ERROR/locust.user.task: 'Response' object has no attribute 'created_at'
Traceback (most recent call last):
  File "/Library/Frameworks/Python.framework/Versions/3.12/lib/python3.12/site-packages/locust/user/task.py", line 340, in run
    self.execute_next_task()
  File "/Library/Frameworks/Python.framework/Versions/3.12/lib/python3.12/site-packages/locust/user/task.py", line 373, in execute_next_task
    self.execute_task(self._task_queue.popleft())
  File "/Library/Frameworks/Python.framework/Versions/3.12/lib/python3.12/site-packages/locust/user/task.py", line 490, in execute_task
    task(self.user)
  File "/Users/chiragkhanduja/PycharmProjects/Hudle_Load/new_partner.py", line 113, in post_data
    created_at = response.created_at
                 ^^^^^^^^^^^^^^^^^^^
AttributeError: 'Response' object has no attribute 'created_at'

[2024-07-22 13:29:02,368] Chirags-Macbook/ERROR/locust.user.task: 'Response' object has no attribute 'created_at'
Traceback (most recent call last):
  File "/Library/Frameworks/Python.framework/Versions/3.12/lib/python3.12/site-packages/locust/user/task.py", line 340, in run
    self.execute_next_task()
  File "/Library/Frameworks/Python.framework/Versions/3.12/lib/python3.12/site-packages/locust/user/task.py", line 373, in execute_next_task
    self.execute_task(self._task_queue.popleft())
  File "/Library/Frameworks/Python.framework/Versions/3.12/lib/python3.12/site-packages/locust/user/task.py", line 490, in execute_task
    task(self.user)
  File "/Users/chiragkhanduja/PycharmProjects/Hudle_Load/new_partner.py", line 113, in post_data
    created_at = response.created_at
                 ^^^^^^^^^^^^^^^^^^^
AttributeError: 'Response' object has no attribute 'created_at'

[2024-07-22 13:29:03,395] Chirags-Macbook/ERROR/locust.user.task: 'Response' object has no attribute 'created_at'
Traceback (most recent call last):
  File "/Library/Frameworks/Python.framework/Versions/3.12/lib/python3.12/site-packages/locust/user/task.py", line 340, in run
    self.execute_next_task()
  File "/Library/Frameworks/Python.framework/Versions/3.12/lib/python3.12/site-packages/locust/user/task.py", line 373, in execute_next_task
    self.execute_task(self._task_queue.popleft())
  File "/Library/Frameworks/Python.framework/Versions/3.12/lib/python3.12/site-packages/locust/user/task.py", line 490, in execute_task
    task(self.user)
  File "/Users/chiragkhanduja/PycharmProjects/Hudle_Load/new_partner.py", line 113, in post_data
    created_at = response.created_at
                 ^^^^^^^^^^^^^^^^^^^
AttributeError: 'Response' object has no attribute 'created_at'

[2024-07-22 13:29:03,434] Chirags-Macbook/ERROR/locust.user.task: 'Response' object has no attribute 'created_at'
Traceback (most recent call last):
  File "/Library/Frameworks/Python.framework/Versions/3.12/lib/python3.12/site-packages/locust/user/task.py", line 340, in run
    self.execute_next_task()
  File "/Library/Frameworks/Python.framework/Versions/3.12/lib/python3.12/site-packages/locust/user/task.py", line 373, in execute_next_task
    self.execute_task(self._task_queue.popleft())
  File "/Library/Frameworks/Python.framework/Versions/3.12/lib/python3.12/site-packages/locust/user/task.py", line 490, in execute_task
    task(self.user)
  File "/Users/chiragkhanduja/PycharmProjects/Hudle_Load/new_partner.py", line 113, in post_data
    created_at = response.created_at
                 ^^^^^^^^^^^^^^^^^^^
AttributeError: 'Response' object has no attribute 'created_at'

[2024-07-22 13:29:03,435] Chirags-Macbook/ERROR/locust.user.task: 'Response' object has no attribute 'created_at'
Traceback (most recent call last):
  File "/Library/Frameworks/Python.framework/Versions/3.12/lib/python3.12/site-packages/locust/user/task.py", line 340, in run
    self.execute_next_task()
  File "/Library/Frameworks/Python.framework/Versions/3.12/lib/python3.12/site-packages/locust/user/task.py", line 373, in execute_next_task
    self.execute_task(self._task_queue.popleft())
  File "/Library/Frameworks/Python.framework/Versions/3.12/lib/python3.12/site-packages/locust/user/task.py", line 490, in execute_task
    task(self.user)
  File "/Users/chiragkhanduja/PycharmProjects/Hudle_Load/new_partner.py", line 113, in post_data
    created_at = response.created_at
                 ^^^^^^^^^^^^^^^^^^^
AttributeError: 'Response' object has no attribute 'created_at'

[2024-07-22 13:29:03,437] Chirags-Macbook/ERROR/locust.user.task: 'Response' object has no attribute 'created_at'
Traceback (most recent call last):
  File "/Library/Frameworks/Python.framework/Versions/3.12/lib/python3.12/site-packages/locust/user/task.py", line 340, in run
    self.execute_next_task()
  File "/Library/Frameworks/Python.framework/Versions/3.12/lib/python3.12/site-packages/locust/user/task.py", line 373, in execute_next_task
    self.execute_task(self._task_queue.popleft())
  File "/Library/Frameworks/Python.framework/Versions/3.12/lib/python3.12/site-packages/locust/user/task.py", line 490, in execute_task
    task(self.user)
  File "/Users/chiragkhanduja/PycharmProjects/Hudle_Load/new_partner.py", line 113, in post_data
    created_at = response.created_at
                 ^^^^^^^^^^^^^^^^^^^
AttributeError: 'Response' object has no attribute 'created_at'

[2024-07-22 13:29:03,498] Chirags-Macbook/ERROR/locust.user.task: 'Response' object has no attribute 'created_at'
Traceback (most recent call last):
  File "/Library/Frameworks/Python.framework/Versions/3.12/lib/python3.12/site-packages/locust/user/task.py", line 340, in run
    self.execute_next_task()
  File "/Library/Frameworks/Python.framework/Versions/3.12/lib/python3.12/site-packages/locust/user/task.py", line 373, in execute_next_task
    self.execute_task(self._task_queue.popleft())
  File "/Library/Frameworks/Python.framework/Versions/3.12/lib/python3.12/site-packages/locust/user/task.py", line 490, in execute_task
    task(self.user)
  File "/Users/chiragkhanduja/PycharmProjects/Hudle_Load/new_partner.py", line 113, in post_data
    created_at = response.created_at
                 ^^^^^^^^^^^^^^^^^^^
AttributeError: 'Response' object has no attribute 'created_at'

[2024-07-22 13:29:03,618] Chirags-Macbook/ERROR/locust.user.task: 'Response' object has no attribute 'created_at'
Traceback (most recent call last):
  File "/Library/Frameworks/Python.framework/Versions/3.12/lib/python3.12/site-packages/locust/user/task.py", line 340, in run
    self.execute_next_task()
  File "/Library/Frameworks/Python.framework/Versions/3.12/lib/python3.12/site-packages/locust/user/task.py", line 373, in execute_next_task
    self.execute_task(self._task_queue.popleft())
  File "/Library/Frameworks/Python.framework/Versions/3.12/lib/python3.12/site-packages/locust/user/task.py", line 490, in execute_task
    task(self.user)
  File "/Users/chiragkhanduja/PycharmProjects/Hudle_Load/new_partner.py", line 113, in post_data
    created_at = response.created_at
                 ^^^^^^^^^^^^^^^^^^^
AttributeError: 'Response' object has no attribute 'created_at'

[2024-07-22 13:29:04,244] Chirags-Macbook/INFO/locust.main: --run-time limit reached, shutting down
[2024-07-22 13:29:04,322] Chirags-Macbook/INFO/locust.main: writing html report to file: repo.html
[2024-07-22 13:29:04,398] Chirags-Macbook/ERROR/root: Uncaught exception in event handler: 
Traceback (most recent call last):
  File "/Library/Frameworks/Python.framework/Versions/3.12/lib/python3.12/site-packages/locust/event.py", line 47, in fire
    handler(**kwargs)
  File "/Users/chiragkhanduja/PycharmProjects/Hudle_Load/new_partner.py", line 158, in on_quitting
    save_to_excel(df, 'response.xlsx')
  File "/Users/chiragkhanduja/PycharmProjects/Hudle_Load/new_partner.py", line 147, in save_to_excel
    format = workbook.add_format({'text_wrap': True, 'valign': 'top', 'border': 1})
             ^^^^^^^^^^^^^^^^^^^
AttributeError: 'Workbook' object has no attribute 'add_format'

[2024-07-22 13:29:04,398] Chirags-Macbook/INFO/locust.main: Shutting down (exit code 1)
[2024-07-22 13:29:35,160] Chirags-Macbook/INFO/locust.main: Run time limit set to 10 seconds
[2024-07-22 13:29:35,160] Chirags-Macbook/INFO/locust.main: Starting Locust 2.28.0
[2024-07-22 13:29:35,160] Chirags-Macbook/INFO/locust.runners: Ramping to 100 users at a rate of 1.00 per second
[2024-07-22 13:29:36,187] Chirags-Macbook/ERROR/locust.user.task: 'Response' object has no attribute 'created_at'
Traceback (most recent call last):
  File "/Library/Frameworks/Python.framework/Versions/3.12/lib/python3.12/site-packages/locust/user/task.py", line 340, in run
    self.execute_next_task()
  File "/Library/Frameworks/Python.framework/Versions/3.12/lib/python3.12/site-packages/locust/user/task.py", line 373, in execute_next_task
    self.execute_task(self._task_queue.popleft())
  File "/Library/Frameworks/Python.framework/Versions/3.12/lib/python3.12/site-packages/locust/user/task.py", line 490, in execute_task
    task(self.user)
  File "/Users/chiragkhanduja/PycharmProjects/Hudle_Load/new_partner.py", line 113, in post_data
    created_at = response.created_at
                 ^^^^^^^^^^^^^^^^^^^
AttributeError: 'Response' object has no attribute 'created_at'

[2024-07-22 13:29:37,102] Chirags-Macbook/ERROR/locust.user.task: 'Response' object has no attribute 'created_at'
Traceback (most recent call last):
  File "/Library/Frameworks/Python.framework/Versions/3.12/lib/python3.12/site-packages/locust/user/task.py", line 340, in run
    self.execute_next_task()
  File "/Library/Frameworks/Python.framework/Versions/3.12/lib/python3.12/site-packages/locust/user/task.py", line 373, in execute_next_task
    self.execute_task(self._task_queue.popleft())
  File "/Library/Frameworks/Python.framework/Versions/3.12/lib/python3.12/site-packages/locust/user/task.py", line 490, in execute_task
    task(self.user)
  File "/Users/chiragkhanduja/PycharmProjects/Hudle_Load/new_partner.py", line 113, in post_data
    created_at = response.created_at
                 ^^^^^^^^^^^^^^^^^^^
AttributeError: 'Response' object has no attribute 'created_at'

[2024-07-22 13:29:38,594] Chirags-Macbook/ERROR/locust.user.task: 'Response' object has no attribute 'created_at'
Traceback (most recent call last):
  File "/Library/Frameworks/Python.framework/Versions/3.12/lib/python3.12/site-packages/locust/user/task.py", line 340, in run
    self.execute_next_task()
  File "/Library/Frameworks/Python.framework/Versions/3.12/lib/python3.12/site-packages/locust/user/task.py", line 373, in execute_next_task
    self.execute_task(self._task_queue.popleft())
  File "/Library/Frameworks/Python.framework/Versions/3.12/lib/python3.12/site-packages/locust/user/task.py", line 490, in execute_task
    task(self.user)
  File "/Users/chiragkhanduja/PycharmProjects/Hudle_Load/new_partner.py", line 113, in post_data
    created_at = response.created_at
                 ^^^^^^^^^^^^^^^^^^^
AttributeError: 'Response' object has no attribute 'created_at'

[2024-07-22 13:29:38,598] Chirags-Macbook/ERROR/locust.user.task: 'Response' object has no attribute 'created_at'
Traceback (most recent call last):
  File "/Library/Frameworks/Python.framework/Versions/3.12/lib/python3.12/site-packages/locust/user/task.py", line 340, in run
    self.execute_next_task()
  File "/Library/Frameworks/Python.framework/Versions/3.12/lib/python3.12/site-packages/locust/user/task.py", line 373, in execute_next_task
    self.execute_task(self._task_queue.popleft())
  File "/Library/Frameworks/Python.framework/Versions/3.12/lib/python3.12/site-packages/locust/user/task.py", line 490, in execute_task
    task(self.user)
  File "/Users/chiragkhanduja/PycharmProjects/Hudle_Load/new_partner.py", line 113, in post_data
    created_at = response.created_at
                 ^^^^^^^^^^^^^^^^^^^
AttributeError: 'Response' object has no attribute 'created_at'

[2024-07-22 13:29:39,699] Chirags-Macbook/ERROR/locust.user.task: 'Response' object has no attribute 'created_at'
Traceback (most recent call last):
  File "/Library/Frameworks/Python.framework/Versions/3.12/lib/python3.12/site-packages/locust/user/task.py", line 340, in run
    self.execute_next_task()
  File "/Library/Frameworks/Python.framework/Versions/3.12/lib/python3.12/site-packages/locust/user/task.py", line 373, in execute_next_task
    self.execute_task(self._task_queue.popleft())
  File "/Library/Frameworks/Python.framework/Versions/3.12/lib/python3.12/site-packages/locust/user/task.py", line 490, in execute_task
    task(self.user)
  File "/Users/chiragkhanduja/PycharmProjects/Hudle_Load/new_partner.py", line 113, in post_data
    created_at = response.created_at
                 ^^^^^^^^^^^^^^^^^^^
AttributeError: 'Response' object has no attribute 'created_at'

[2024-07-22 13:29:39,701] Chirags-Macbook/ERROR/locust.user.task: 'Response' object has no attribute 'created_at'
Traceback (most recent call last):
  File "/Library/Frameworks/Python.framework/Versions/3.12/lib/python3.12/site-packages/locust/user/task.py", line 340, in run
    self.execute_next_task()
  File "/Library/Frameworks/Python.framework/Versions/3.12/lib/python3.12/site-packages/locust/user/task.py", line 373, in execute_next_task
    self.execute_task(self._task_queue.popleft())
  File "/Library/Frameworks/Python.framework/Versions/3.12/lib/python3.12/site-packages/locust/user/task.py", line 490, in execute_task
    task(self.user)
  File "/Users/chiragkhanduja/PycharmProjects/Hudle_Load/new_partner.py", line 113, in post_data
    created_at = response.created_at
                 ^^^^^^^^^^^^^^^^^^^
AttributeError: 'Response' object has no attribute 'created_at'

[2024-07-22 13:29:40,317] Chirags-Macbook/ERROR/locust.user.task: 'Response' object has no attribute 'created_at'
Traceback (most recent call last):
  File "/Library/Frameworks/Python.framework/Versions/3.12/lib/python3.12/site-packages/locust/user/task.py", line 340, in run
    self.execute_next_task()
  File "/Library/Frameworks/Python.framework/Versions/3.12/lib/python3.12/site-packages/locust/user/task.py", line 373, in execute_next_task
    self.execute_task(self._task_queue.popleft())
  File "/Library/Frameworks/Python.framework/Versions/3.12/lib/python3.12/site-packages/locust/user/task.py", line 490, in execute_task
    task(self.user)
  File "/Users/chiragkhanduja/PycharmProjects/Hudle_Load/new_partner.py", line 113, in post_data
    created_at = response.created_at
                 ^^^^^^^^^^^^^^^^^^^
AttributeError: 'Response' object has no attribute 'created_at'

[2024-07-22 13:29:40,428] Chirags-Macbook/ERROR/locust.user.task: 'Response' object has no attribute 'created_at'
Traceback (most recent call last):
  File "/Library/Frameworks/Python.framework/Versions/3.12/lib/python3.12/site-packages/locust/user/task.py", line 340, in run
    self.execute_next_task()
  File "/Library/Frameworks/Python.framework/Versions/3.12/lib/python3.12/site-packages/locust/user/task.py", line 373, in execute_next_task
    self.execute_task(self._task_queue.popleft())
  File "/Library/Frameworks/Python.framework/Versions/3.12/lib/python3.12/site-packages/locust/user/task.py", line 490, in execute_task
    task(self.user)
  File "/Users/chiragkhanduja/PycharmProjects/Hudle_Load/new_partner.py", line 113, in post_data
    created_at = response.created_at
                 ^^^^^^^^^^^^^^^^^^^
AttributeError: 'Response' object has no attribute 'created_at'

[2024-07-22 13:29:40,745] Chirags-Macbook/ERROR/locust.user.task: 'Response' object has no attribute 'created_at'
Traceback (most recent call last):
  File "/Library/Frameworks/Python.framework/Versions/3.12/lib/python3.12/site-packages/locust/user/task.py", line 340, in run
    self.execute_next_task()
  File "/Library/Frameworks/Python.framework/Versions/3.12/lib/python3.12/site-packages/locust/user/task.py", line 373, in execute_next_task
    self.execute_task(self._task_queue.popleft())
  File "/Library/Frameworks/Python.framework/Versions/3.12/lib/python3.12/site-packages/locust/user/task.py", line 490, in execute_task
    task(self.user)
  File "/Users/chiragkhanduja/PycharmProjects/Hudle_Load/new_partner.py", line 113, in post_data
    created_at = response.created_at
                 ^^^^^^^^^^^^^^^^^^^
AttributeError: 'Response' object has no attribute 'created_at'

[2024-07-22 13:29:40,996] Chirags-Macbook/INFO/locust.main: writing html report to file: repo.html
[2024-07-22 13:29:41,091] Chirags-Macbook/ERROR/root: Uncaught exception in event handler: 
Traceback (most recent call last):
  File "/Library/Frameworks/Python.framework/Versions/3.12/lib/python3.12/site-packages/locust/event.py", line 47, in fire
    handler(**kwargs)
  File "/Users/chiragkhanduja/PycharmProjects/Hudle_Load/new_partner.py", line 158, in on_quitting
    save_to_excel(df, 'response.xlsx')
  File "/Users/chiragkhanduja/PycharmProjects/Hudle_Load/new_partner.py", line 147, in save_to_excel
    format = workbook.add_format({'text_wrap': True, 'valign': 'top', 'border': 1})
             ^^^^^^^^^^^^^^^^^^^
AttributeError: 'Workbook' object has no attribute 'add_format'

[2024-07-22 13:29:41,092] Chirags-Macbook/INFO/locust.main: Shutting down (exit code 1)
[2024-07-22 13:32:54,537] Chirags-Macbook/INFO/locust.main: Run time limit set to 10 seconds
[2024-07-22 13:32:54,537] Chirags-Macbook/INFO/locust.main: Starting Locust 2.28.0
[2024-07-22 13:32:54,537] Chirags-Macbook/INFO/locust.runners: Ramping to 100 users at a rate of 1.00 per second
[2024-07-22 13:32:55,321] Chirags-Macbook/ERROR/locust.user.task: 'Response' object has no attribute 'created_at'
Traceback (most recent call last):
  File "/Library/Frameworks/Python.framework/Versions/3.12/lib/python3.12/site-packages/locust/user/task.py", line 340, in run
    self.execute_next_task()
  File "/Library/Frameworks/Python.framework/Versions/3.12/lib/python3.12/site-packages/locust/user/task.py", line 373, in execute_next_task
    self.execute_task(self._task_queue.popleft())
  File "/Library/Frameworks/Python.framework/Versions/3.12/lib/python3.12/site-packages/locust/user/task.py", line 490, in execute_task
    task(self.user)
  File "/Users/chiragkhanduja/PycharmProjects/Hudle_Load/new_partner.py", line 113, in post_data
    created_at = response.created_at
                 ^^^^^^^^^^^^^^^^^^^
AttributeError: 'Response' object has no attribute 'created_at'

[2024-07-22 13:32:56,529] Chirags-Macbook/ERROR/locust.user.task: 'Response' object has no attribute 'created_at'
Traceback (most recent call last):
  File "/Library/Frameworks/Python.framework/Versions/3.12/lib/python3.12/site-packages/locust/user/task.py", line 340, in run
    self.execute_next_task()
  File "/Library/Frameworks/Python.framework/Versions/3.12/lib/python3.12/site-packages/locust/user/task.py", line 373, in execute_next_task
    self.execute_task(self._task_queue.popleft())
  File "/Library/Frameworks/Python.framework/Versions/3.12/lib/python3.12/site-packages/locust/user/task.py", line 490, in execute_task
    task(self.user)
  File "/Users/chiragkhanduja/PycharmProjects/Hudle_Load/new_partner.py", line 113, in post_data
    created_at = response.created_at
                 ^^^^^^^^^^^^^^^^^^^
AttributeError: 'Response' object has no attribute 'created_at'

[2024-07-22 13:32:57,534] Chirags-Macbook/ERROR/locust.user.task: 'Response' object has no attribute 'created_at'
Traceback (most recent call last):
  File "/Library/Frameworks/Python.framework/Versions/3.12/lib/python3.12/site-packages/locust/user/task.py", line 340, in run
    self.execute_next_task()
  File "/Library/Frameworks/Python.framework/Versions/3.12/lib/python3.12/site-packages/locust/user/task.py", line 373, in execute_next_task
    self.execute_task(self._task_queue.popleft())
  File "/Library/Frameworks/Python.framework/Versions/3.12/lib/python3.12/site-packages/locust/user/task.py", line 490, in execute_task
    task(self.user)
  File "/Users/chiragkhanduja/PycharmProjects/Hudle_Load/new_partner.py", line 113, in post_data
    created_at = response.created_at
                 ^^^^^^^^^^^^^^^^^^^
AttributeError: 'Response' object has no attribute 'created_at'

[2024-07-22 13:32:57,810] Chirags-Macbook/ERROR/locust.user.task: 'Response' object has no attribute 'created_at'
Traceback (most recent call last):
  File "/Library/Frameworks/Python.framework/Versions/3.12/lib/python3.12/site-packages/locust/user/task.py", line 340, in run
    self.execute_next_task()
  File "/Library/Frameworks/Python.framework/Versions/3.12/lib/python3.12/site-packages/locust/user/task.py", line 373, in execute_next_task
    self.execute_task(self._task_queue.popleft())
  File "/Library/Frameworks/Python.framework/Versions/3.12/lib/python3.12/site-packages/locust/user/task.py", line 490, in execute_task
    task(self.user)
  File "/Users/chiragkhanduja/PycharmProjects/Hudle_Load/new_partner.py", line 113, in post_data
    created_at = response.created_at
                 ^^^^^^^^^^^^^^^^^^^
AttributeError: 'Response' object has no attribute 'created_at'

[2024-07-22 13:32:58,421] Chirags-Macbook/ERROR/locust.user.task: 'Response' object has no attribute 'created_at'
Traceback (most recent call last):
  File "/Library/Frameworks/Python.framework/Versions/3.12/lib/python3.12/site-packages/locust/user/task.py", line 340, in run
    self.execute_next_task()
  File "/Library/Frameworks/Python.framework/Versions/3.12/lib/python3.12/site-packages/locust/user/task.py", line 373, in execute_next_task
    self.execute_task(self._task_queue.popleft())
  File "/Library/Frameworks/Python.framework/Versions/3.12/lib/python3.12/site-packages/locust/user/task.py", line 490, in execute_task
    task(self.user)
  File "/Users/chiragkhanduja/PycharmProjects/Hudle_Load/new_partner.py", line 113, in post_data
    created_at = response.created_at
                 ^^^^^^^^^^^^^^^^^^^
AttributeError: 'Response' object has no attribute 'created_at'

[2024-07-22 13:32:58,564] Chirags-Macbook/ERROR/locust.user.task: 'Response' object has no attribute 'created_at'
Traceback (most recent call last):
  File "/Library/Frameworks/Python.framework/Versions/3.12/lib/python3.12/site-packages/locust/user/task.py", line 340, in run
    self.execute_next_task()
  File "/Library/Frameworks/Python.framework/Versions/3.12/lib/python3.12/site-packages/locust/user/task.py", line 373, in execute_next_task
    self.execute_task(self._task_queue.popleft())
  File "/Library/Frameworks/Python.framework/Versions/3.12/lib/python3.12/site-packages/locust/user/task.py", line 490, in execute_task
    task(self.user)
  File "/Users/chiragkhanduja/PycharmProjects/Hudle_Load/new_partner.py", line 113, in post_data
    created_at = response.created_at
                 ^^^^^^^^^^^^^^^^^^^
AttributeError: 'Response' object has no attribute 'created_at'

[2024-07-22 13:32:58,892] Chirags-Macbook/INFO/locust.main: writing html report to file: repo.html
[2024-07-22 13:32:58,987] Chirags-Macbook/ERROR/root: Uncaught exception in event handler: 
Traceback (most recent call last):
  File "/Library/Frameworks/Python.framework/Versions/3.12/lib/python3.12/site-packages/locust/event.py", line 47, in fire
    handler(**kwargs)
  File "/Users/chiragkhanduja/PycharmProjects/Hudle_Load/new_partner.py", line 158, in on_quitting
    save_to_excel(df, 'response.xlsx')
  File "/Users/chiragkhanduja/PycharmProjects/Hudle_Load/new_partner.py", line 147, in save_to_excel
    format = workbook.add_format({'text_wrap': True, 'valign': 'top', 'border': 1})
             ^^^^^^^^^^^^^^^^^^^
AttributeError: 'Workbook' object has no attribute 'add_format'

[2024-07-22 13:32:58,987] Chirags-Macbook/INFO/locust.main: Shutting down (exit code 1)
[2024-07-22 13:33:10,648] Chirags-Macbook/INFO/locust.main: Run time limit set to 10 seconds
[2024-07-22 13:33:10,648] Chirags-Macbook/INFO/locust.main: Starting Locust 2.28.0
[2024-07-22 13:33:10,649] Chirags-Macbook/INFO/locust.runners: Ramping to 100 users at a rate of 1.00 per second
[2024-07-22 13:33:11,604] Chirags-Macbook/ERROR/locust.user.task: 'Response' object has no attribute 'created_at'
Traceback (most recent call last):
  File "/Library/Frameworks/Python.framework/Versions/3.12/lib/python3.12/site-packages/locust/user/task.py", line 340, in run
    self.execute_next_task()
  File "/Library/Frameworks/Python.framework/Versions/3.12/lib/python3.12/site-packages/locust/user/task.py", line 373, in execute_next_task
    self.execute_task(self._task_queue.popleft())
  File "/Library/Frameworks/Python.framework/Versions/3.12/lib/python3.12/site-packages/locust/user/task.py", line 490, in execute_task
    task(self.user)
  File "/Users/chiragkhanduja/PycharmProjects/Hudle_Load/new_partner.py", line 113, in post_data
    created_at = response.created_at
                 ^^^^^^^^^^^^^^^^^^^
AttributeError: 'Response' object has no attribute 'created_at'

[2024-07-22 13:33:12,632] Chirags-Macbook/ERROR/locust.user.task: 'Response' object has no attribute 'created_at'
Traceback (most recent call last):
  File "/Library/Frameworks/Python.framework/Versions/3.12/lib/python3.12/site-packages/locust/user/task.py", line 340, in run
    self.execute_next_task()
  File "/Library/Frameworks/Python.framework/Versions/3.12/lib/python3.12/site-packages/locust/user/task.py", line 373, in execute_next_task
    self.execute_task(self._task_queue.popleft())
  File "/Library/Frameworks/Python.framework/Versions/3.12/lib/python3.12/site-packages/locust/user/task.py", line 490, in execute_task
    task(self.user)
  File "/Users/chiragkhanduja/PycharmProjects/Hudle_Load/new_partner.py", line 113, in post_data
    created_at = response.created_at
                 ^^^^^^^^^^^^^^^^^^^
AttributeError: 'Response' object has no attribute 'created_at'

[2024-07-22 13:33:13,654] Chirags-Macbook/ERROR/locust.user.task: 'Response' object has no attribute 'created_at'
Traceback (most recent call last):
  File "/Library/Frameworks/Python.framework/Versions/3.12/lib/python3.12/site-packages/locust/user/task.py", line 340, in run
    self.execute_next_task()
  File "/Library/Frameworks/Python.framework/Versions/3.12/lib/python3.12/site-packages/locust/user/task.py", line 373, in execute_next_task
    self.execute_task(self._task_queue.popleft())
  File "/Library/Frameworks/Python.framework/Versions/3.12/lib/python3.12/site-packages/locust/user/task.py", line 490, in execute_task
    task(self.user)
  File "/Users/chiragkhanduja/PycharmProjects/Hudle_Load/new_partner.py", line 113, in post_data
    created_at = response.created_at
                 ^^^^^^^^^^^^^^^^^^^
AttributeError: 'Response' object has no attribute 'created_at'

[2024-07-22 13:33:13,862] Chirags-Macbook/ERROR/locust.user.task: 'Response' object has no attribute 'created_at'
Traceback (most recent call last):
  File "/Library/Frameworks/Python.framework/Versions/3.12/lib/python3.12/site-packages/locust/user/task.py", line 340, in run
    self.execute_next_task()
  File "/Library/Frameworks/Python.framework/Versions/3.12/lib/python3.12/site-packages/locust/user/task.py", line 373, in execute_next_task
    self.execute_task(self._task_queue.popleft())
  File "/Library/Frameworks/Python.framework/Versions/3.12/lib/python3.12/site-packages/locust/user/task.py", line 490, in execute_task
    task(self.user)
  File "/Users/chiragkhanduja/PycharmProjects/Hudle_Load/new_partner.py", line 113, in post_data
    created_at = response.created_at
                 ^^^^^^^^^^^^^^^^^^^
AttributeError: 'Response' object has no attribute 'created_at'

[2024-07-22 13:33:14,254] Chirags-Macbook/ERROR/locust.user.task: 'Response' object has no attribute 'created_at'
Traceback (most recent call last):
  File "/Library/Frameworks/Python.framework/Versions/3.12/lib/python3.12/site-packages/locust/user/task.py", line 340, in run
    self.execute_next_task()
  File "/Library/Frameworks/Python.framework/Versions/3.12/lib/python3.12/site-packages/locust/user/task.py", line 373, in execute_next_task
    self.execute_task(self._task_queue.popleft())
  File "/Library/Frameworks/Python.framework/Versions/3.12/lib/python3.12/site-packages/locust/user/task.py", line 490, in execute_task
    task(self.user)
  File "/Users/chiragkhanduja/PycharmProjects/Hudle_Load/new_partner.py", line 113, in post_data
    created_at = response.created_at
                 ^^^^^^^^^^^^^^^^^^^
AttributeError: 'Response' object has no attribute 'created_at'

[2024-07-22 13:33:14,330] Chirags-Macbook/ERROR/locust.user.task: 'Response' object has no attribute 'created_at'
Traceback (most recent call last):
  File "/Library/Frameworks/Python.framework/Versions/3.12/lib/python3.12/site-packages/locust/user/task.py", line 340, in run
    self.execute_next_task()
  File "/Library/Frameworks/Python.framework/Versions/3.12/lib/python3.12/site-packages/locust/user/task.py", line 373, in execute_next_task
    self.execute_task(self._task_queue.popleft())
  File "/Library/Frameworks/Python.framework/Versions/3.12/lib/python3.12/site-packages/locust/user/task.py", line 490, in execute_task
    task(self.user)
  File "/Users/chiragkhanduja/PycharmProjects/Hudle_Load/new_partner.py", line 113, in post_data
    created_at = response.created_at
                 ^^^^^^^^^^^^^^^^^^^
AttributeError: 'Response' object has no attribute 'created_at'

[2024-07-22 13:33:14,626] Chirags-Macbook/INFO/locust.main: writing html report to file: repo.html
[2024-07-22 13:33:14,719] Chirags-Macbook/ERROR/root: Uncaught exception in event handler: 
Traceback (most recent call last):
  File "/Library/Frameworks/Python.framework/Versions/3.12/lib/python3.12/site-packages/locust/event.py", line 47, in fire
    handler(**kwargs)
  File "/Users/chiragkhanduja/PycharmProjects/Hudle_Load/new_partner.py", line 158, in on_quitting
    save_to_excel(df, 'response.xlsx')
  File "/Users/chiragkhanduja/PycharmProjects/Hudle_Load/new_partner.py", line 147, in save_to_excel
    format = workbook.add_format({'text_wrap': True, 'valign': 'top', 'border': 1})
             ^^^^^^^^^^^^^^^^^^^
AttributeError: 'Workbook' object has no attribute 'add_format'

[2024-07-22 13:33:14,719] Chirags-Macbook/INFO/locust.main: Shutting down (exit code 1)
[2024-07-22 13:33:35,676] Chirags-Macbook/INFO/locust.main: Run time limit set to 10 seconds
[2024-07-22 13:33:35,676] Chirags-Macbook/INFO/locust.main: Starting Locust 2.28.0
[2024-07-22 13:33:35,677] Chirags-Macbook/INFO/locust.runners: Ramping to 100 users at a rate of 1.00 per second
[2024-07-22 13:33:36,719] Chirags-Macbook/ERROR/locust.user.task: 'id'
Traceback (most recent call last):
  File "/Library/Frameworks/Python.framework/Versions/3.12/lib/python3.12/site-packages/locust/user/task.py", line 340, in run
    self.execute_next_task()
  File "/Library/Frameworks/Python.framework/Versions/3.12/lib/python3.12/site-packages/locust/user/task.py", line 373, in execute_next_task
    self.execute_task(self._task_queue.popleft())
  File "/Library/Frameworks/Python.framework/Versions/3.12/lib/python3.12/site-packages/locust/user/task.py", line 490, in execute_task
    task(self.user)
  File "/Users/chiragkhanduja/PycharmProjects/Hudle_Load/new_partner.py", line 122, in post_data
    'id': data['id'],
          ~~~~^^^^^^
KeyError: 'id'

[2024-07-22 13:33:37,667] Chirags-Macbook/ERROR/locust.user.task: 'id'
Traceback (most recent call last):
  File "/Library/Frameworks/Python.framework/Versions/3.12/lib/python3.12/site-packages/locust/user/task.py", line 340, in run
    self.execute_next_task()
  File "/Library/Frameworks/Python.framework/Versions/3.12/lib/python3.12/site-packages/locust/user/task.py", line 373, in execute_next_task
    self.execute_task(self._task_queue.popleft())
  File "/Library/Frameworks/Python.framework/Versions/3.12/lib/python3.12/site-packages/locust/user/task.py", line 490, in execute_task
    task(self.user)
  File "/Users/chiragkhanduja/PycharmProjects/Hudle_Load/new_partner.py", line 122, in post_data
    'id': data['id'],
          ~~~~^^^^^^
KeyError: 'id'

[2024-07-22 13:33:38,883] Chirags-Macbook/ERROR/locust.user.task: 'id'
Traceback (most recent call last):
  File "/Library/Frameworks/Python.framework/Versions/3.12/lib/python3.12/site-packages/locust/user/task.py", line 340, in run
    self.execute_next_task()
  File "/Library/Frameworks/Python.framework/Versions/3.12/lib/python3.12/site-packages/locust/user/task.py", line 373, in execute_next_task
    self.execute_task(self._task_queue.popleft())
  File "/Library/Frameworks/Python.framework/Versions/3.12/lib/python3.12/site-packages/locust/user/task.py", line 490, in execute_task
    task(self.user)
  File "/Users/chiragkhanduja/PycharmProjects/Hudle_Load/new_partner.py", line 122, in post_data
    'id': data['id'],
          ~~~~^^^^^^
KeyError: 'id'

[2024-07-22 13:33:38,884] Chirags-Macbook/ERROR/locust.user.task: 'id'
Traceback (most recent call last):
  File "/Library/Frameworks/Python.framework/Versions/3.12/lib/python3.12/site-packages/locust/user/task.py", line 340, in run
    self.execute_next_task()
  File "/Library/Frameworks/Python.framework/Versions/3.12/lib/python3.12/site-packages/locust/user/task.py", line 373, in execute_next_task
    self.execute_task(self._task_queue.popleft())
  File "/Library/Frameworks/Python.framework/Versions/3.12/lib/python3.12/site-packages/locust/user/task.py", line 490, in execute_task
    task(self.user)
  File "/Users/chiragkhanduja/PycharmProjects/Hudle_Load/new_partner.py", line 122, in post_data
    'id': data['id'],
          ~~~~^^^^^^
KeyError: 'id'

[2024-07-22 13:33:39,795] Chirags-Macbook/ERROR/locust.user.task: 'id'
Traceback (most recent call last):
  File "/Library/Frameworks/Python.framework/Versions/3.12/lib/python3.12/site-packages/locust/user/task.py", line 340, in run
    self.execute_next_task()
  File "/Library/Frameworks/Python.framework/Versions/3.12/lib/python3.12/site-packages/locust/user/task.py", line 373, in execute_next_task
    self.execute_task(self._task_queue.popleft())
  File "/Library/Frameworks/Python.framework/Versions/3.12/lib/python3.12/site-packages/locust/user/task.py", line 490, in execute_task
    task(self.user)
  File "/Users/chiragkhanduja/PycharmProjects/Hudle_Load/new_partner.py", line 122, in post_data
    'id': data['id'],
          ~~~~^^^^^^
KeyError: 'id'

[2024-07-22 13:33:39,812] Chirags-Macbook/ERROR/locust.user.task: 'id'
Traceback (most recent call last):
  File "/Library/Frameworks/Python.framework/Versions/3.12/lib/python3.12/site-packages/locust/user/task.py", line 340, in run
    self.execute_next_task()
  File "/Library/Frameworks/Python.framework/Versions/3.12/lib/python3.12/site-packages/locust/user/task.py", line 373, in execute_next_task
    self.execute_task(self._task_queue.popleft())
  File "/Library/Frameworks/Python.framework/Versions/3.12/lib/python3.12/site-packages/locust/user/task.py", line 490, in execute_task
    task(self.user)
  File "/Users/chiragkhanduja/PycharmProjects/Hudle_Load/new_partner.py", line 122, in post_data
    'id': data['id'],
          ~~~~^^^^^^
KeyError: 'id'

[2024-07-22 13:33:40,928] Chirags-Macbook/INFO/locust.main: writing html report to file: repo.html
[2024-07-22 13:33:41,022] Chirags-Macbook/ERROR/root: Uncaught exception in event handler: 
Traceback (most recent call last):
  File "/Library/Frameworks/Python.framework/Versions/3.12/lib/python3.12/site-packages/locust/event.py", line 47, in fire
    handler(**kwargs)
  File "/Users/chiragkhanduja/PycharmProjects/Hudle_Load/new_partner.py", line 157, in on_quitting
    save_to_excel(df, 'response.xlsx')
  File "/Users/chiragkhanduja/PycharmProjects/Hudle_Load/new_partner.py", line 146, in save_to_excel
    format = workbook.add_format({'text_wrap': True, 'valign': 'top', 'border': 1})
             ^^^^^^^^^^^^^^^^^^^
AttributeError: 'Workbook' object has no attribute 'add_format'

[2024-07-22 13:33:41,023] Chirags-Macbook/INFO/locust.main: Shutting down (exit code 1)
[2024-07-22 16:15:57,489] Chirags-Macbook/INFO/locust.main: Run time limit set to 10 seconds
[2024-07-22 16:15:57,490] Chirags-Macbook/INFO/locust.main: Starting Locust 2.28.0
[2024-07-22 16:15:57,490] Chirags-Macbook/INFO/locust.runners: Ramping to 100 users at a rate of 1.00 per second
[2024-07-22 16:15:58,309] Chirags-Macbook/ERROR/locust.user.task: 'id'
Traceback (most recent call last):
  File "/Library/Frameworks/Python.framework/Versions/3.12/lib/python3.12/site-packages/locust/user/task.py", line 340, in run
    self.execute_next_task()
  File "/Library/Frameworks/Python.framework/Versions/3.12/lib/python3.12/site-packages/locust/user/task.py", line 373, in execute_next_task
    self.execute_task(self._task_queue.popleft())
  File "/Library/Frameworks/Python.framework/Versions/3.12/lib/python3.12/site-packages/locust/user/task.py", line 490, in execute_task
    task(self.user)
  File "/Users/chiragkhanduja/PycharmProjects/Hudle_Load/new_partner.py", line 122, in post_data
    'id': data['id'],
          ~~~~^^^^^^
KeyError: 'id'

[2024-07-22 16:15:59,227] Chirags-Macbook/ERROR/locust.user.task: 'id'
Traceback (most recent call last):
  File "/Library/Frameworks/Python.framework/Versions/3.12/lib/python3.12/site-packages/locust/user/task.py", line 340, in run
    self.execute_next_task()
  File "/Library/Frameworks/Python.framework/Versions/3.12/lib/python3.12/site-packages/locust/user/task.py", line 373, in execute_next_task
    self.execute_task(self._task_queue.popleft())
  File "/Library/Frameworks/Python.framework/Versions/3.12/lib/python3.12/site-packages/locust/user/task.py", line 490, in execute_task
    task(self.user)
  File "/Users/chiragkhanduja/PycharmProjects/Hudle_Load/new_partner.py", line 122, in post_data
    'id': data['id'],
          ~~~~^^^^^^
KeyError: 'id'

[2024-07-22 16:15:59,765] Chirags-Macbook/ERROR/locust.user.task: 'id'
Traceback (most recent call last):
  File "/Library/Frameworks/Python.framework/Versions/3.12/lib/python3.12/site-packages/locust/user/task.py", line 340, in run
    self.execute_next_task()
  File "/Library/Frameworks/Python.framework/Versions/3.12/lib/python3.12/site-packages/locust/user/task.py", line 373, in execute_next_task
    self.execute_task(self._task_queue.popleft())
  File "/Library/Frameworks/Python.framework/Versions/3.12/lib/python3.12/site-packages/locust/user/task.py", line 490, in execute_task
    task(self.user)
  File "/Users/chiragkhanduja/PycharmProjects/Hudle_Load/new_partner.py", line 122, in post_data
    'id': data['id'],
          ~~~~^^^^^^
KeyError: 'id'

[2024-07-22 16:16:00,515] Chirags-Macbook/ERROR/locust.user.task: 'id'
Traceback (most recent call last):
  File "/Library/Frameworks/Python.framework/Versions/3.12/lib/python3.12/site-packages/locust/user/task.py", line 340, in run
    self.execute_next_task()
  File "/Library/Frameworks/Python.framework/Versions/3.12/lib/python3.12/site-packages/locust/user/task.py", line 373, in execute_next_task
    self.execute_task(self._task_queue.popleft())
  File "/Library/Frameworks/Python.framework/Versions/3.12/lib/python3.12/site-packages/locust/user/task.py", line 490, in execute_task
    task(self.user)
  File "/Users/chiragkhanduja/PycharmProjects/Hudle_Load/new_partner.py", line 122, in post_data
    'id': data['id'],
          ~~~~^^^^^^
KeyError: 'id'

[2024-07-22 16:16:00,744] Chirags-Macbook/ERROR/locust.user.task: 'id'
Traceback (most recent call last):
  File "/Library/Frameworks/Python.framework/Versions/3.12/lib/python3.12/site-packages/locust/user/task.py", line 340, in run
    self.execute_next_task()
  File "/Library/Frameworks/Python.framework/Versions/3.12/lib/python3.12/site-packages/locust/user/task.py", line 373, in execute_next_task
    self.execute_task(self._task_queue.popleft())
  File "/Library/Frameworks/Python.framework/Versions/3.12/lib/python3.12/site-packages/locust/user/task.py", line 490, in execute_task
    task(self.user)
  File "/Users/chiragkhanduja/PycharmProjects/Hudle_Load/new_partner.py", line 122, in post_data
    'id': data['id'],
          ~~~~^^^^^^
KeyError: 'id'

[2024-07-22 16:16:01,098] Chirags-Macbook/ERROR/locust.user.task: 'id'
Traceback (most recent call last):
  File "/Library/Frameworks/Python.framework/Versions/3.12/lib/python3.12/site-packages/locust/user/task.py", line 340, in run
    self.execute_next_task()
  File "/Library/Frameworks/Python.framework/Versions/3.12/lib/python3.12/site-packages/locust/user/task.py", line 373, in execute_next_task
    self.execute_task(self._task_queue.popleft())
  File "/Library/Frameworks/Python.framework/Versions/3.12/lib/python3.12/site-packages/locust/user/task.py", line 490, in execute_task
    task(self.user)
  File "/Users/chiragkhanduja/PycharmProjects/Hudle_Load/new_partner.py", line 122, in post_data
    'id': data['id'],
          ~~~~^^^^^^
KeyError: 'id'

[2024-07-22 16:16:01,521] Chirags-Macbook/ERROR/locust.user.task: 'id'
Traceback (most recent call last):
  File "/Library/Frameworks/Python.framework/Versions/3.12/lib/python3.12/site-packages/locust/user/task.py", line 340, in run
    self.execute_next_task()
  File "/Library/Frameworks/Python.framework/Versions/3.12/lib/python3.12/site-packages/locust/user/task.py", line 373, in execute_next_task
    self.execute_task(self._task_queue.popleft())
  File "/Library/Frameworks/Python.framework/Versions/3.12/lib/python3.12/site-packages/locust/user/task.py", line 490, in execute_task
    task(self.user)
  File "/Users/chiragkhanduja/PycharmProjects/Hudle_Load/new_partner.py", line 122, in post_data
    'id': data['id'],
          ~~~~^^^^^^
KeyError: 'id'

[2024-07-22 16:16:02,120] Chirags-Macbook/ERROR/locust.user.task: 'id'
Traceback (most recent call last):
  File "/Library/Frameworks/Python.framework/Versions/3.12/lib/python3.12/site-packages/locust/user/task.py", line 340, in run
    self.execute_next_task()
  File "/Library/Frameworks/Python.framework/Versions/3.12/lib/python3.12/site-packages/locust/user/task.py", line 373, in execute_next_task
    self.execute_task(self._task_queue.popleft())
  File "/Library/Frameworks/Python.framework/Versions/3.12/lib/python3.12/site-packages/locust/user/task.py", line 490, in execute_task
    task(self.user)
  File "/Users/chiragkhanduja/PycharmProjects/Hudle_Load/new_partner.py", line 122, in post_data
    'id': data['id'],
          ~~~~^^^^^^
KeyError: 'id'

[2024-07-22 16:16:02,513] Chirags-Macbook/ERROR/locust.user.task: 'id'
Traceback (most recent call last):
  File "/Library/Frameworks/Python.framework/Versions/3.12/lib/python3.12/site-packages/locust/user/task.py", line 340, in run
    self.execute_next_task()
  File "/Library/Frameworks/Python.framework/Versions/3.12/lib/python3.12/site-packages/locust/user/task.py", line 373, in execute_next_task
    self.execute_task(self._task_queue.popleft())
  File "/Library/Frameworks/Python.framework/Versions/3.12/lib/python3.12/site-packages/locust/user/task.py", line 490, in execute_task
    task(self.user)
  File "/Users/chiragkhanduja/PycharmProjects/Hudle_Load/new_partner.py", line 122, in post_data
    'id': data['id'],
          ~~~~^^^^^^
KeyError: 'id'

[2024-07-22 16:16:02,661] Chirags-Macbook/ERROR/locust.user.task: 'id'
Traceback (most recent call last):
  File "/Library/Frameworks/Python.framework/Versions/3.12/lib/python3.12/site-packages/locust/user/task.py", line 340, in run
    self.execute_next_task()
  File "/Library/Frameworks/Python.framework/Versions/3.12/lib/python3.12/site-packages/locust/user/task.py", line 373, in execute_next_task
    self.execute_task(self._task_queue.popleft())
  File "/Library/Frameworks/Python.framework/Versions/3.12/lib/python3.12/site-packages/locust/user/task.py", line 490, in execute_task
    task(self.user)
  File "/Users/chiragkhanduja/PycharmProjects/Hudle_Load/new_partner.py", line 122, in post_data
    'id': data['id'],
          ~~~~^^^^^^
KeyError: 'id'

[2024-07-22 16:16:03,225] Chirags-Macbook/ERROR/locust.user.task: 'id'
Traceback (most recent call last):
  File "/Library/Frameworks/Python.framework/Versions/3.12/lib/python3.12/site-packages/locust/user/task.py", line 340, in run
    self.execute_next_task()
  File "/Library/Frameworks/Python.framework/Versions/3.12/lib/python3.12/site-packages/locust/user/task.py", line 373, in execute_next_task
    self.execute_task(self._task_queue.popleft())
  File "/Library/Frameworks/Python.framework/Versions/3.12/lib/python3.12/site-packages/locust/user/task.py", line 490, in execute_task
    task(self.user)
  File "/Users/chiragkhanduja/PycharmProjects/Hudle_Load/new_partner.py", line 122, in post_data
    'id': data['id'],
          ~~~~^^^^^^
KeyError: 'id'

[2024-07-22 16:16:03,227] Chirags-Macbook/ERROR/locust.user.task: 'id'
Traceback (most recent call last):
  File "/Library/Frameworks/Python.framework/Versions/3.12/lib/python3.12/site-packages/locust/user/task.py", line 340, in run
    self.execute_next_task()
  File "/Library/Frameworks/Python.framework/Versions/3.12/lib/python3.12/site-packages/locust/user/task.py", line 373, in execute_next_task
    self.execute_task(self._task_queue.popleft())
  File "/Library/Frameworks/Python.framework/Versions/3.12/lib/python3.12/site-packages/locust/user/task.py", line 490, in execute_task
    task(self.user)
  File "/Users/chiragkhanduja/PycharmProjects/Hudle_Load/new_partner.py", line 122, in post_data
    'id': data['id'],
          ~~~~^^^^^^
KeyError: 'id'

[2024-07-22 16:16:03,723] Chirags-Macbook/INFO/locust.main: writing html report to file: repo.html
[2024-07-22 16:16:03,868] Chirags-Macbook/ERROR/root: Uncaught exception in event handler: 
Traceback (most recent call last):
  File "/Library/Frameworks/Python.framework/Versions/3.12/lib/python3.12/site-packages/locust/event.py", line 47, in fire
    handler(**kwargs)
  File "/Users/chiragkhanduja/PycharmProjects/Hudle_Load/new_partner.py", line 157, in on_quitting
    save_to_excel(df, 'response.xlsx')
  File "/Users/chiragkhanduja/PycharmProjects/Hudle_Load/new_partner.py", line 146, in save_to_excel
    format = workbook.add_format({'text_wrap': True, 'valign': 'top', 'border': 1})
             ^^^^^^^^^^^^^^^^^^^
AttributeError: 'Workbook' object has no attribute 'add_format'

[2024-07-22 16:16:03,868] Chirags-Macbook/INFO/locust.main: Shutting down (exit code 1)
[2024-07-22 16:17:29,611] Chirags-Macbook/INFO/locust.main: Run time limit set to 10 seconds
[2024-07-22 16:17:29,612] Chirags-Macbook/INFO/locust.main: Starting Locust 2.28.0
[2024-07-22 16:17:29,612] Chirags-Macbook/INFO/locust.runners: Ramping to 100 users at a rate of 1.00 per second
[2024-07-22 16:17:33,890] Chirags-Macbook/INFO/locust.main: writing html report to file: repo.html
[2024-07-22 16:17:33,968] Chirags-Macbook/ERROR/root: Uncaught exception in event handler: 
Traceback (most recent call last):
  File "/Library/Frameworks/Python.framework/Versions/3.12/lib/python3.12/site-packages/locust/event.py", line 47, in fire
    handler(**kwargs)
  File "/Users/chiragkhanduja/PycharmProjects/Hudle_Load/new_partner.py", line 157, in on_quitting
    save_to_excel(df, 'response.xlsx')
  File "/Users/chiragkhanduja/PycharmProjects/Hudle_Load/new_partner.py", line 146, in save_to_excel
    format = workbook.add_format({'text_wrap': True, 'valign': 'top', 'border': 1})
             ^^^^^^^^^^^^^^^^^^^
AttributeError: 'Workbook' object has no attribute 'add_format'

[2024-07-22 16:17:33,969] Chirags-Macbook/INFO/locust.main: Shutting down (exit code 2)
[2024-07-22 16:17:57,379] Chirags-Macbook/INFO/locust.main: Run time limit set to 10 seconds
[2024-07-22 16:17:57,379] Chirags-Macbook/INFO/locust.main: Starting Locust 2.28.0
[2024-07-22 16:17:57,380] Chirags-Macbook/INFO/locust.runners: Ramping to 100 users at a rate of 1.00 per second
[2024-07-22 16:17:57,947] Chirags-Macbook/ERROR/locust.user.task: 'id'
Traceback (most recent call last):
  File "/Library/Frameworks/Python.framework/Versions/3.12/lib/python3.12/site-packages/locust/user/task.py", line 340, in run
    self.execute_next_task()
  File "/Library/Frameworks/Python.framework/Versions/3.12/lib/python3.12/site-packages/locust/user/task.py", line 373, in execute_next_task
    self.execute_task(self._task_queue.popleft())
  File "/Library/Frameworks/Python.framework/Versions/3.12/lib/python3.12/site-packages/locust/user/task.py", line 490, in execute_task
    task(self.user)
  File "/Users/chiragkhanduja/PycharmProjects/Hudle_Load/new_partner.py", line 121, in post_data
    'id': data['id'],
          ~~~~^^^^^^
KeyError: 'id'

[2024-07-22 16:17:59,038] Chirags-Macbook/ERROR/locust.user.task: 'id'
Traceback (most recent call last):
  File "/Library/Frameworks/Python.framework/Versions/3.12/lib/python3.12/site-packages/locust/user/task.py", line 340, in run
    self.execute_next_task()
  File "/Library/Frameworks/Python.framework/Versions/3.12/lib/python3.12/site-packages/locust/user/task.py", line 373, in execute_next_task
    self.execute_task(self._task_queue.popleft())
  File "/Library/Frameworks/Python.framework/Versions/3.12/lib/python3.12/site-packages/locust/user/task.py", line 490, in execute_task
    task(self.user)
  File "/Users/chiragkhanduja/PycharmProjects/Hudle_Load/new_partner.py", line 121, in post_data
    'id': data['id'],
          ~~~~^^^^^^
KeyError: 'id'

[2024-07-22 16:17:59,689] Chirags-Macbook/ERROR/locust.user.task: 'id'
Traceback (most recent call last):
  File "/Library/Frameworks/Python.framework/Versions/3.12/lib/python3.12/site-packages/locust/user/task.py", line 340, in run
    self.execute_next_task()
  File "/Library/Frameworks/Python.framework/Versions/3.12/lib/python3.12/site-packages/locust/user/task.py", line 373, in execute_next_task
    self.execute_task(self._task_queue.popleft())
  File "/Library/Frameworks/Python.framework/Versions/3.12/lib/python3.12/site-packages/locust/user/task.py", line 490, in execute_task
    task(self.user)
  File "/Users/chiragkhanduja/PycharmProjects/Hudle_Load/new_partner.py", line 121, in post_data
    'id': data['id'],
          ~~~~^^^^^^
KeyError: 'id'

[2024-07-22 16:18:00,343] Chirags-Macbook/ERROR/locust.user.task: 'id'
Traceback (most recent call last):
  File "/Library/Frameworks/Python.framework/Versions/3.12/lib/python3.12/site-packages/locust/user/task.py", line 340, in run
    self.execute_next_task()
  File "/Library/Frameworks/Python.framework/Versions/3.12/lib/python3.12/site-packages/locust/user/task.py", line 373, in execute_next_task
    self.execute_task(self._task_queue.popleft())
  File "/Library/Frameworks/Python.framework/Versions/3.12/lib/python3.12/site-packages/locust/user/task.py", line 490, in execute_task
    task(self.user)
  File "/Users/chiragkhanduja/PycharmProjects/Hudle_Load/new_partner.py", line 121, in post_data
    'id': data['id'],
          ~~~~^^^^^^
KeyError: 'id'

[2024-07-22 16:18:00,570] Chirags-Macbook/ERROR/locust.user.task: 'id'
Traceback (most recent call last):
  File "/Library/Frameworks/Python.framework/Versions/3.12/lib/python3.12/site-packages/locust/user/task.py", line 340, in run
    self.execute_next_task()
  File "/Library/Frameworks/Python.framework/Versions/3.12/lib/python3.12/site-packages/locust/user/task.py", line 373, in execute_next_task
    self.execute_task(self._task_queue.popleft())
  File "/Library/Frameworks/Python.framework/Versions/3.12/lib/python3.12/site-packages/locust/user/task.py", line 490, in execute_task
    task(self.user)
  File "/Users/chiragkhanduja/PycharmProjects/Hudle_Load/new_partner.py", line 121, in post_data
    'id': data['id'],
          ~~~~^^^^^^
KeyError: 'id'

[2024-07-22 16:18:00,936] Chirags-Macbook/ERROR/locust.user.task: 'id'
Traceback (most recent call last):
  File "/Library/Frameworks/Python.framework/Versions/3.12/lib/python3.12/site-packages/locust/user/task.py", line 340, in run
    self.execute_next_task()
  File "/Library/Frameworks/Python.framework/Versions/3.12/lib/python3.12/site-packages/locust/user/task.py", line 373, in execute_next_task
    self.execute_task(self._task_queue.popleft())
  File "/Library/Frameworks/Python.framework/Versions/3.12/lib/python3.12/site-packages/locust/user/task.py", line 490, in execute_task
    task(self.user)
  File "/Users/chiragkhanduja/PycharmProjects/Hudle_Load/new_partner.py", line 121, in post_data
    'id': data['id'],
          ~~~~^^^^^^
KeyError: 'id'

[2024-07-22 16:18:01,648] Chirags-Macbook/ERROR/locust.user.task: 'id'
Traceback (most recent call last):
  File "/Library/Frameworks/Python.framework/Versions/3.12/lib/python3.12/site-packages/locust/user/task.py", line 340, in run
    self.execute_next_task()
  File "/Library/Frameworks/Python.framework/Versions/3.12/lib/python3.12/site-packages/locust/user/task.py", line 373, in execute_next_task
    self.execute_task(self._task_queue.popleft())
  File "/Library/Frameworks/Python.framework/Versions/3.12/lib/python3.12/site-packages/locust/user/task.py", line 490, in execute_task
    task(self.user)
  File "/Users/chiragkhanduja/PycharmProjects/Hudle_Load/new_partner.py", line 121, in post_data
    'id': data['id'],
          ~~~~^^^^^^
KeyError: 'id'

[2024-07-22 16:18:01,985] Chirags-Macbook/ERROR/locust.user.task: 'id'
Traceback (most recent call last):
  File "/Library/Frameworks/Python.framework/Versions/3.12/lib/python3.12/site-packages/locust/user/task.py", line 340, in run
    self.execute_next_task()
  File "/Library/Frameworks/Python.framework/Versions/3.12/lib/python3.12/site-packages/locust/user/task.py", line 373, in execute_next_task
    self.execute_task(self._task_queue.popleft())
  File "/Library/Frameworks/Python.framework/Versions/3.12/lib/python3.12/site-packages/locust/user/task.py", line 490, in execute_task
    task(self.user)
  File "/Users/chiragkhanduja/PycharmProjects/Hudle_Load/new_partner.py", line 121, in post_data
    'id': data['id'],
          ~~~~^^^^^^
KeyError: 'id'

[2024-07-22 16:18:02,423] Chirags-Macbook/ERROR/locust.user.task: 'id'
Traceback (most recent call last):
  File "/Library/Frameworks/Python.framework/Versions/3.12/lib/python3.12/site-packages/locust/user/task.py", line 340, in run
    self.execute_next_task()
  File "/Library/Frameworks/Python.framework/Versions/3.12/lib/python3.12/site-packages/locust/user/task.py", line 373, in execute_next_task
    self.execute_task(self._task_queue.popleft())
  File "/Library/Frameworks/Python.framework/Versions/3.12/lib/python3.12/site-packages/locust/user/task.py", line 490, in execute_task
    task(self.user)
  File "/Users/chiragkhanduja/PycharmProjects/Hudle_Load/new_partner.py", line 121, in post_data
    'id': data['id'],
          ~~~~^^^^^^
KeyError: 'id'

[2024-07-22 16:18:02,724] Chirags-Macbook/ERROR/locust.user.task: 'id'
Traceback (most recent call last):
  File "/Library/Frameworks/Python.framework/Versions/3.12/lib/python3.12/site-packages/locust/user/task.py", line 340, in run
    self.execute_next_task()
  File "/Library/Frameworks/Python.framework/Versions/3.12/lib/python3.12/site-packages/locust/user/task.py", line 373, in execute_next_task
    self.execute_task(self._task_queue.popleft())
  File "/Library/Frameworks/Python.framework/Versions/3.12/lib/python3.12/site-packages/locust/user/task.py", line 490, in execute_task
    task(self.user)
  File "/Users/chiragkhanduja/PycharmProjects/Hudle_Load/new_partner.py", line 121, in post_data
    'id': data['id'],
          ~~~~^^^^^^
KeyError: 'id'

[2024-07-22 16:18:02,785] Chirags-Macbook/ERROR/locust.user.task: 'id'
Traceback (most recent call last):
  File "/Library/Frameworks/Python.framework/Versions/3.12/lib/python3.12/site-packages/locust/user/task.py", line 340, in run
    self.execute_next_task()
  File "/Library/Frameworks/Python.framework/Versions/3.12/lib/python3.12/site-packages/locust/user/task.py", line 373, in execute_next_task
    self.execute_task(self._task_queue.popleft())
  File "/Library/Frameworks/Python.framework/Versions/3.12/lib/python3.12/site-packages/locust/user/task.py", line 490, in execute_task
    task(self.user)
  File "/Users/chiragkhanduja/PycharmProjects/Hudle_Load/new_partner.py", line 121, in post_data
    'id': data['id'],
          ~~~~^^^^^^
KeyError: 'id'

[2024-07-22 16:18:02,973] Chirags-Macbook/ERROR/locust.user.task: 'id'
Traceback (most recent call last):
  File "/Library/Frameworks/Python.framework/Versions/3.12/lib/python3.12/site-packages/locust/user/task.py", line 340, in run
    self.execute_next_task()
  File "/Library/Frameworks/Python.framework/Versions/3.12/lib/python3.12/site-packages/locust/user/task.py", line 373, in execute_next_task
    self.execute_task(self._task_queue.popleft())
  File "/Library/Frameworks/Python.framework/Versions/3.12/lib/python3.12/site-packages/locust/user/task.py", line 490, in execute_task
    task(self.user)
  File "/Users/chiragkhanduja/PycharmProjects/Hudle_Load/new_partner.py", line 121, in post_data
    'id': data['id'],
          ~~~~^^^^^^
KeyError: 'id'

[2024-07-22 16:18:03,205] Chirags-Macbook/INFO/locust.main: writing html report to file: repo.html
[2024-07-22 16:18:03,284] Chirags-Macbook/ERROR/root: Uncaught exception in event handler: 
Traceback (most recent call last):
  File "/Library/Frameworks/Python.framework/Versions/3.12/lib/python3.12/site-packages/locust/event.py", line 47, in fire
    handler(**kwargs)
  File "/Users/chiragkhanduja/PycharmProjects/Hudle_Load/new_partner.py", line 158, in on_quitting
    save_to_excel(df, 'response.xlsx')
  File "/Users/chiragkhanduja/PycharmProjects/Hudle_Load/new_partner.py", line 147, in save_to_excel
    format = workbook.add_format({'text_wrap': True, 'valign': 'top', 'border': 1})
             ^^^^^^^^^^^^^^^^^^^
AttributeError: 'Workbook' object has no attribute 'add_format'

[2024-07-22 16:18:03,284] Chirags-Macbook/INFO/locust.main: Shutting down (exit code 1)
[2024-07-23 09:09:56,435] Chirags-Macbook/INFO/locust.main: Run time limit set to 10 seconds
[2024-07-23 09:09:56,435] Chirags-Macbook/INFO/locust.main: Starting Locust 2.28.0
[2024-07-23 09:09:56,437] Chirags-Macbook/INFO/locust.runners: Ramping to 100 users at a rate of 1.00 per second
[2024-07-23 09:09:57,122] Chirags-Macbook/ERROR/locust.user.task: string indices must be integers, not 'str'
Traceback (most recent call last):
  File "/Library/Frameworks/Python.framework/Versions/3.12/lib/python3.12/site-packages/locust/user/task.py", line 340, in run
    self.execute_next_task()
  File "/Library/Frameworks/Python.framework/Versions/3.12/lib/python3.12/site-packages/locust/user/task.py", line 373, in execute_next_task
    self.execute_task(self._task_queue.popleft())
  File "/Library/Frameworks/Python.framework/Versions/3.12/lib/python3.12/site-packages/locust/user/task.py", line 490, in execute_task
    task(self.user)
  File "/Users/chiragkhanduja/PycharmProjects/Hudle_Load/new_partner.py", line 121, in post_data
    'id': response.text['id'],
          ~~~~~~~~~~~~~^^^^^^
TypeError: string indices must be integers, not 'str'

[2024-07-23 09:09:57,836] Chirags-Macbook/ERROR/locust.user.task: string indices must be integers, not 'str'
Traceback (most recent call last):
  File "/Library/Frameworks/Python.framework/Versions/3.12/lib/python3.12/site-packages/locust/user/task.py", line 340, in run
    self.execute_next_task()
  File "/Library/Frameworks/Python.framework/Versions/3.12/lib/python3.12/site-packages/locust/user/task.py", line 373, in execute_next_task
    self.execute_task(self._task_queue.popleft())
  File "/Library/Frameworks/Python.framework/Versions/3.12/lib/python3.12/site-packages/locust/user/task.py", line 490, in execute_task
    task(self.user)
  File "/Users/chiragkhanduja/PycharmProjects/Hudle_Load/new_partner.py", line 121, in post_data
    'id': response.text['id'],
          ~~~~~~~~~~~~~^^^^^^
TypeError: string indices must be integers, not 'str'

[2024-07-23 09:09:58,516] Chirags-Macbook/ERROR/locust.user.task: string indices must be integers, not 'str'
Traceback (most recent call last):
  File "/Library/Frameworks/Python.framework/Versions/3.12/lib/python3.12/site-packages/locust/user/task.py", line 340, in run
    self.execute_next_task()
  File "/Library/Frameworks/Python.framework/Versions/3.12/lib/python3.12/site-packages/locust/user/task.py", line 373, in execute_next_task
    self.execute_task(self._task_queue.popleft())
  File "/Library/Frameworks/Python.framework/Versions/3.12/lib/python3.12/site-packages/locust/user/task.py", line 490, in execute_task
    task(self.user)
  File "/Users/chiragkhanduja/PycharmProjects/Hudle_Load/new_partner.py", line 121, in post_data
    'id': response.text['id'],
          ~~~~~~~~~~~~~^^^^^^
TypeError: string indices must be integers, not 'str'

[2024-07-23 09:09:58,822] Chirags-Macbook/ERROR/locust.user.task: string indices must be integers, not 'str'
Traceback (most recent call last):
  File "/Library/Frameworks/Python.framework/Versions/3.12/lib/python3.12/site-packages/locust/user/task.py", line 340, in run
    self.execute_next_task()
  File "/Library/Frameworks/Python.framework/Versions/3.12/lib/python3.12/site-packages/locust/user/task.py", line 373, in execute_next_task
    self.execute_task(self._task_queue.popleft())
  File "/Library/Frameworks/Python.framework/Versions/3.12/lib/python3.12/site-packages/locust/user/task.py", line 490, in execute_task
    task(self.user)
  File "/Users/chiragkhanduja/PycharmProjects/Hudle_Load/new_partner.py", line 121, in post_data
    'id': response.text['id'],
          ~~~~~~~~~~~~~^^^^^^
TypeError: string indices must be integers, not 'str'

[2024-07-23 09:09:59,386] Chirags-Macbook/ERROR/locust.user.task: string indices must be integers, not 'str'
Traceback (most recent call last):
  File "/Library/Frameworks/Python.framework/Versions/3.12/lib/python3.12/site-packages/locust/user/task.py", line 340, in run
    self.execute_next_task()
  File "/Library/Frameworks/Python.framework/Versions/3.12/lib/python3.12/site-packages/locust/user/task.py", line 373, in execute_next_task
    self.execute_task(self._task_queue.popleft())
  File "/Library/Frameworks/Python.framework/Versions/3.12/lib/python3.12/site-packages/locust/user/task.py", line 490, in execute_task
    task(self.user)
  File "/Users/chiragkhanduja/PycharmProjects/Hudle_Load/new_partner.py", line 121, in post_data
    'id': response.text['id'],
          ~~~~~~~~~~~~~^^^^^^
TypeError: string indices must be integers, not 'str'

[2024-07-23 09:09:59,829] Chirags-Macbook/ERROR/locust.user.task: string indices must be integers, not 'str'
Traceback (most recent call last):
  File "/Library/Frameworks/Python.framework/Versions/3.12/lib/python3.12/site-packages/locust/user/task.py", line 340, in run
    self.execute_next_task()
  File "/Library/Frameworks/Python.framework/Versions/3.12/lib/python3.12/site-packages/locust/user/task.py", line 373, in execute_next_task
    self.execute_task(self._task_queue.popleft())
  File "/Library/Frameworks/Python.framework/Versions/3.12/lib/python3.12/site-packages/locust/user/task.py", line 490, in execute_task
    task(self.user)
  File "/Users/chiragkhanduja/PycharmProjects/Hudle_Load/new_partner.py", line 121, in post_data
    'id': response.text['id'],
          ~~~~~~~~~~~~~^^^^^^
TypeError: string indices must be integers, not 'str'

[2024-07-23 09:10:00,482] Chirags-Macbook/ERROR/locust.user.task: string indices must be integers, not 'str'
Traceback (most recent call last):
  File "/Library/Frameworks/Python.framework/Versions/3.12/lib/python3.12/site-packages/locust/user/task.py", line 340, in run
    self.execute_next_task()
  File "/Library/Frameworks/Python.framework/Versions/3.12/lib/python3.12/site-packages/locust/user/task.py", line 373, in execute_next_task
    self.execute_task(self._task_queue.popleft())
  File "/Library/Frameworks/Python.framework/Versions/3.12/lib/python3.12/site-packages/locust/user/task.py", line 490, in execute_task
    task(self.user)
  File "/Users/chiragkhanduja/PycharmProjects/Hudle_Load/new_partner.py", line 121, in post_data
    'id': response.text['id'],
          ~~~~~~~~~~~~~^^^^^^
TypeError: string indices must be integers, not 'str'

[2024-07-23 09:10:00,819] Chirags-Macbook/ERROR/locust.user.task: string indices must be integers, not 'str'
Traceback (most recent call last):
  File "/Library/Frameworks/Python.framework/Versions/3.12/lib/python3.12/site-packages/locust/user/task.py", line 340, in run
    self.execute_next_task()
  File "/Library/Frameworks/Python.framework/Versions/3.12/lib/python3.12/site-packages/locust/user/task.py", line 373, in execute_next_task
    self.execute_task(self._task_queue.popleft())
  File "/Library/Frameworks/Python.framework/Versions/3.12/lib/python3.12/site-packages/locust/user/task.py", line 490, in execute_task
    task(self.user)
  File "/Users/chiragkhanduja/PycharmProjects/Hudle_Load/new_partner.py", line 121, in post_data
    'id': response.text['id'],
          ~~~~~~~~~~~~~^^^^^^
TypeError: string indices must be integers, not 'str'

[2024-07-23 09:10:00,867] Chirags-Macbook/INFO/locust.main: writing html report to file: repo.html
[2024-07-23 09:10:01,070] Chirags-Macbook/ERROR/root: Uncaught exception in event handler: 
Traceback (most recent call last):
  File "/Library/Frameworks/Python.framework/Versions/3.12/lib/python3.12/site-packages/locust/event.py", line 47, in fire
    handler(**kwargs)
  File "/Users/chiragkhanduja/PycharmProjects/Hudle_Load/new_partner.py", line 158, in on_quitting
    save_to_excel(df, 'response.xlsx')
  File "/Users/chiragkhanduja/PycharmProjects/Hudle_Load/new_partner.py", line 147, in save_to_excel
    format = workbook.add_format({'text_wrap': True, 'valign': 'top', 'border': 1})
             ^^^^^^^^^^^^^^^^^^^
AttributeError: 'Workbook' object has no attribute 'add_format'

[2024-07-23 09:10:01,071] Chirags-Macbook/INFO/locust.main: Shutting down (exit code 1)
[2024-07-23 09:10:41,480] Chirags-Macbook/INFO/locust.main: Run time limit set to 10 seconds
[2024-07-23 09:10:41,481] Chirags-Macbook/INFO/locust.main: Starting Locust 2.28.0
[2024-07-23 09:10:41,482] Chirags-Macbook/INFO/locust.runners: Ramping to 100 users at a rate of 1.00 per second
[2024-07-23 09:10:47,646] Chirags-Macbook/INFO/locust.main: writing html report to file: repo.html
[2024-07-23 09:10:47,869] Chirags-Macbook/ERROR/root: Uncaught exception in event handler: 
Traceback (most recent call last):
  File "/Library/Frameworks/Python.framework/Versions/3.12/lib/python3.12/site-packages/locust/event.py", line 47, in fire
    handler(**kwargs)
  File "/Users/chiragkhanduja/PycharmProjects/Hudle_Load/new_partner.py", line 158, in on_quitting
    save_to_excel(df, 'response.xlsx')
  File "/Users/chiragkhanduja/PycharmProjects/Hudle_Load/new_partner.py", line 147, in save_to_excel
    format = workbook.add_format({'text_wrap': True, 'valign': 'top', 'border': 1})
             ^^^^^^^^^^^^^^^^^^^
AttributeError: 'Workbook' object has no attribute 'add_format'

[2024-07-23 09:10:47,870] Chirags-Macbook/INFO/locust.main: Shutting down (exit code 1)
[2024-07-23 12:58:08,255] Chirags-Macbook/INFO/locust.main: Run time limit set to 10 seconds
[2024-07-23 12:58:08,256] Chirags-Macbook/INFO/locust.main: Starting Locust 2.28.0
[2024-07-23 12:58:08,256] Chirags-Macbook/INFO/locust.runners: Ramping to 100 users at a rate of 1.00 per second
[2024-07-23 12:58:11,806] Chirags-Macbook/INFO/locust.main: writing html report to file: repo.html
[2024-07-23 12:58:11,949] Chirags-Macbook/ERROR/root: Uncaught exception in event handler: 
Traceback (most recent call last):
  File "/Library/Frameworks/Python.framework/Versions/3.12/lib/python3.12/site-packages/locust/event.py", line 47, in fire
    handler(**kwargs)
  File "/Users/chiragkhanduja/PycharmProjects/Hudle_Load/new_partner.py", line 158, in on_quitting
    save_to_excel(df, 'response.xlsx')
  File "/Users/chiragkhanduja/PycharmProjects/Hudle_Load/new_partner.py", line 147, in save_to_excel
    format = workbook.add_format({'text_wrap': True, 'valign': 'top', 'border': 1})
             ^^^^^^^^^^^^^^^^^^^
AttributeError: 'Workbook' object has no attribute 'add_format'

[2024-07-23 12:58:11,949] Chirags-Macbook/INFO/locust.main: Shutting down (exit code 1)
[2024-07-23 13:04:05,269] Chirags-Macbook/INFO/locust.main: Run time limit set to 10 seconds
[2024-07-23 13:04:05,269] Chirags-Macbook/INFO/locust.main: Starting Locust 2.28.0
[2024-07-23 13:04:05,269] Chirags-Macbook/INFO/locust.runners: Ramping to 100 users at a rate of 1.00 per second
[2024-07-23 13:04:08,225] Chirags-Macbook/INFO/locust.main: writing html report to file: repo.html
[2024-07-23 13:04:08,318] Chirags-Macbook/ERROR/root: Uncaught exception in event handler: 
Traceback (most recent call last):
  File "/Library/Frameworks/Python.framework/Versions/3.12/lib/python3.12/site-packages/locust/event.py", line 47, in fire
    handler(**kwargs)
  File "/Users/chiragkhanduja/PycharmProjects/Hudle_Load/new_partner.py", line 158, in on_quitting
    save_to_excel(df, 'response.xlsx')
  File "/Users/chiragkhanduja/PycharmProjects/Hudle_Load/new_partner.py", line 147, in save_to_excel
    format = workbook.add_format({'text_wrap': True, 'valign': 'top', 'border': 1})
             ^^^^^^^^^^^^^^^^^^^
AttributeError: 'Workbook' object has no attribute 'add_format'

[2024-07-23 13:04:08,318] Chirags-Macbook/INFO/locust.main: Shutting down (exit code 2)
[2024-07-23 13:34:24,187] Chirags-Macbook/INFO/locust.main: Run time limit set to 10 seconds
[2024-07-23 13:34:24,187] Chirags-Macbook/INFO/locust.main: Starting Locust 2.28.0
[2024-07-23 13:34:24,187] Chirags-Macbook/INFO/locust.runners: Ramping to 100 users at a rate of 1.00 per second
[2024-07-23 13:34:31,864] Chirags-Macbook/INFO/locust.main: writing html report to file: repo.html
[2024-07-23 13:34:31,946] Chirags-Macbook/ERROR/root: Uncaught exception in event handler: 
Traceback (most recent call last):
  File "/Library/Frameworks/Python.framework/Versions/3.12/lib/python3.12/site-packages/locust/event.py", line 47, in fire
    handler(**kwargs)
  File "/Users/chiragkhanduja/PycharmProjects/Hudle_Load/new_partner.py", line 158, in on_quitting
    save_to_excel(df, 'response.xlsx')
  File "/Users/chiragkhanduja/PycharmProjects/Hudle_Load/new_partner.py", line 147, in save_to_excel
    format = workbook.add_format({'text_wrap': True, 'valign': 'top', 'border': 1})
             ^^^^^^^^^^^^^^^^^^^
AttributeError: 'Workbook' object has no attribute 'add_format'

[2024-07-23 13:34:31,946] Chirags-Macbook/INFO/locust.main: Shutting down (exit code 2)
[2024-07-23 13:45:49,923] Chirags-Macbook/INFO/locust.main: Run time limit set to 10 seconds
[2024-07-23 13:45:49,923] Chirags-Macbook/INFO/locust.main: Starting Locust 2.28.0
[2024-07-23 13:45:49,923] Chirags-Macbook/INFO/locust.runners: Ramping to 100 users at a rate of 1.00 per second
[2024-07-23 13:45:59,440] Chirags-Macbook/INFO/locust.main: --run-time limit reached, shutting down
[2024-07-23 13:45:59,516] Chirags-Macbook/INFO/locust.main: writing html report to file: repo.html
[2024-07-23 13:45:59,594] Chirags-Macbook/ERROR/root: Uncaught exception in event handler: 
Traceback (most recent call last):
  File "/Library/Frameworks/Python.framework/Versions/3.12/lib/python3.12/site-packages/locust/event.py", line 47, in fire
    handler(**kwargs)
  File "/Users/chiragkhanduja/PycharmProjects/Hudle_Load/new_partner.py", line 159, in on_quitting
    save_to_excel(df, 'response.xlsx')
  File "/Users/chiragkhanduja/PycharmProjects/Hudle_Load/new_partner.py", line 148, in save_to_excel
    format = workbook.add_format({'text_wrap': True, 'valign': 'top', 'border': 1})
             ^^^^^^^^^^^^^^^^^^^
AttributeError: 'Workbook' object has no attribute 'add_format'

[2024-07-23 13:45:59,595] Chirags-Macbook/INFO/locust.main: Shutting down (exit code 2)
[2024-07-23 13:47:59,959] Chirags-Macbook/INFO/locust.main: Run time limit set to 10 seconds
[2024-07-23 13:47:59,959] Chirags-Macbook/INFO/locust.main: Starting Locust 2.28.0
[2024-07-23 13:47:59,960] Chirags-Macbook/INFO/locust.runners: Ramping to 100 users at a rate of 1.00 per second
[2024-07-23 13:48:00,671] Chirags-Macbook/ERROR/locust.user.task: 'code'
Traceback (most recent call last):
  File "/Library/Frameworks/Python.framework/Versions/3.12/lib/python3.12/site-packages/locust/user/task.py", line 340, in run
    self.execute_next_task()
  File "/Library/Frameworks/Python.framework/Versions/3.12/lib/python3.12/site-packages/locust/user/task.py", line 373, in execute_next_task
    self.execute_task(self._task_queue.popleft())
  File "/Library/Frameworks/Python.framework/Versions/3.12/lib/python3.12/site-packages/locust/user/task.py", line 490, in execute_task
    task(self.user)
  File "/Users/chiragkhanduja/PycharmProjects/Hudle_Load/new_partner.py", line 124, in post_data
    'Code': response_data['data']['code']
            ~~~~~~~~~~~~~~~~~~~~~^^^^^^^^
KeyError: 'code'

[2024-07-23 13:48:01,585] Chirags-Macbook/ERROR/locust.user.task: 'code'
Traceback (most recent call last):
  File "/Library/Frameworks/Python.framework/Versions/3.12/lib/python3.12/site-packages/locust/user/task.py", line 340, in run
    self.execute_next_task()
  File "/Library/Frameworks/Python.framework/Versions/3.12/lib/python3.12/site-packages/locust/user/task.py", line 373, in execute_next_task
    self.execute_task(self._task_queue.popleft())
  File "/Library/Frameworks/Python.framework/Versions/3.12/lib/python3.12/site-packages/locust/user/task.py", line 490, in execute_task
    task(self.user)
  File "/Users/chiragkhanduja/PycharmProjects/Hudle_Load/new_partner.py", line 124, in post_data
    'Code': response_data['data']['code']
            ~~~~~~~~~~~~~~~~~~~~~^^^^^^^^
KeyError: 'code'

[2024-07-23 13:48:02,408] Chirags-Macbook/ERROR/locust.user.task: 'code'
Traceback (most recent call last):
  File "/Library/Frameworks/Python.framework/Versions/3.12/lib/python3.12/site-packages/locust/user/task.py", line 340, in run
    self.execute_next_task()
  File "/Library/Frameworks/Python.framework/Versions/3.12/lib/python3.12/site-packages/locust/user/task.py", line 373, in execute_next_task
    self.execute_task(self._task_queue.popleft())
  File "/Library/Frameworks/Python.framework/Versions/3.12/lib/python3.12/site-packages/locust/user/task.py", line 490, in execute_task
    task(self.user)
  File "/Users/chiragkhanduja/PycharmProjects/Hudle_Load/new_partner.py", line 124, in post_data
    'Code': response_data['data']['code']
            ~~~~~~~~~~~~~~~~~~~~~^^^^^^^^
KeyError: 'code'

[2024-07-23 13:48:02,558] Chirags-Macbook/ERROR/locust.user.task: 'code'
Traceback (most recent call last):
  File "/Library/Frameworks/Python.framework/Versions/3.12/lib/python3.12/site-packages/locust/user/task.py", line 340, in run
    self.execute_next_task()
  File "/Library/Frameworks/Python.framework/Versions/3.12/lib/python3.12/site-packages/locust/user/task.py", line 373, in execute_next_task
    self.execute_task(self._task_queue.popleft())
  File "/Library/Frameworks/Python.framework/Versions/3.12/lib/python3.12/site-packages/locust/user/task.py", line 490, in execute_task
    task(self.user)
  File "/Users/chiragkhanduja/PycharmProjects/Hudle_Load/new_partner.py", line 124, in post_data
    'Code': response_data['data']['code']
            ~~~~~~~~~~~~~~~~~~~~~^^^^^^^^
KeyError: 'code'

[2024-07-23 13:48:03,512] Chirags-Macbook/ERROR/locust.user.task: 'code'
Traceback (most recent call last):
  File "/Library/Frameworks/Python.framework/Versions/3.12/lib/python3.12/site-packages/locust/user/task.py", line 340, in run
    self.execute_next_task()
  File "/Library/Frameworks/Python.framework/Versions/3.12/lib/python3.12/site-packages/locust/user/task.py", line 373, in execute_next_task
    self.execute_task(self._task_queue.popleft())
  File "/Library/Frameworks/Python.framework/Versions/3.12/lib/python3.12/site-packages/locust/user/task.py", line 490, in execute_task
    task(self.user)
  File "/Users/chiragkhanduja/PycharmProjects/Hudle_Load/new_partner.py", line 124, in post_data
    'Code': response_data['data']['code']
            ~~~~~~~~~~~~~~~~~~~~~^^^^^^^^
KeyError: 'code'

[2024-07-23 13:48:03,841] Chirags-Macbook/ERROR/locust.user.task: 'code'
Traceback (most recent call last):
  File "/Library/Frameworks/Python.framework/Versions/3.12/lib/python3.12/site-packages/locust/user/task.py", line 340, in run
    self.execute_next_task()
  File "/Library/Frameworks/Python.framework/Versions/3.12/lib/python3.12/site-packages/locust/user/task.py", line 373, in execute_next_task
    self.execute_task(self._task_queue.popleft())
  File "/Library/Frameworks/Python.framework/Versions/3.12/lib/python3.12/site-packages/locust/user/task.py", line 490, in execute_task
    task(self.user)
  File "/Users/chiragkhanduja/PycharmProjects/Hudle_Load/new_partner.py", line 124, in post_data
    'Code': response_data['data']['code']
            ~~~~~~~~~~~~~~~~~~~~~^^^^^^^^
KeyError: 'code'

[2024-07-23 13:48:04,577] Chirags-Macbook/ERROR/locust.user.task: 'code'
Traceback (most recent call last):
  File "/Library/Frameworks/Python.framework/Versions/3.12/lib/python3.12/site-packages/locust/user/task.py", line 340, in run
    self.execute_next_task()
  File "/Library/Frameworks/Python.framework/Versions/3.12/lib/python3.12/site-packages/locust/user/task.py", line 373, in execute_next_task
    self.execute_task(self._task_queue.popleft())
  File "/Library/Frameworks/Python.framework/Versions/3.12/lib/python3.12/site-packages/locust/user/task.py", line 490, in execute_task
    task(self.user)
  File "/Users/chiragkhanduja/PycharmProjects/Hudle_Load/new_partner.py", line 124, in post_data
    'Code': response_data['data']['code']
            ~~~~~~~~~~~~~~~~~~~~~^^^^^^^^
KeyError: 'code'

[2024-07-23 13:48:04,580] Chirags-Macbook/ERROR/locust.user.task: 'code'
Traceback (most recent call last):
  File "/Library/Frameworks/Python.framework/Versions/3.12/lib/python3.12/site-packages/locust/user/task.py", line 340, in run
    self.execute_next_task()
  File "/Library/Frameworks/Python.framework/Versions/3.12/lib/python3.12/site-packages/locust/user/task.py", line 373, in execute_next_task
    self.execute_task(self._task_queue.popleft())
  File "/Library/Frameworks/Python.framework/Versions/3.12/lib/python3.12/site-packages/locust/user/task.py", line 490, in execute_task
    task(self.user)
  File "/Users/chiragkhanduja/PycharmProjects/Hudle_Load/new_partner.py", line 124, in post_data
    'Code': response_data['data']['code']
            ~~~~~~~~~~~~~~~~~~~~~^^^^^^^^
KeyError: 'code'

[2024-07-23 13:48:04,634] Chirags-Macbook/ERROR/locust.user.task: 'code'
Traceback (most recent call last):
  File "/Library/Frameworks/Python.framework/Versions/3.12/lib/python3.12/site-packages/locust/user/task.py", line 340, in run
    self.execute_next_task()
  File "/Library/Frameworks/Python.framework/Versions/3.12/lib/python3.12/site-packages/locust/user/task.py", line 373, in execute_next_task
    self.execute_task(self._task_queue.popleft())
  File "/Library/Frameworks/Python.framework/Versions/3.12/lib/python3.12/site-packages/locust/user/task.py", line 490, in execute_task
    task(self.user)
  File "/Users/chiragkhanduja/PycharmProjects/Hudle_Load/new_partner.py", line 124, in post_data
    'Code': response_data['data']['code']
            ~~~~~~~~~~~~~~~~~~~~~^^^^^^^^
KeyError: 'code'

[2024-07-23 13:48:05,198] Chirags-Macbook/ERROR/locust.user.task: 'code'
Traceback (most recent call last):
  File "/Library/Frameworks/Python.framework/Versions/3.12/lib/python3.12/site-packages/locust/user/task.py", line 340, in run
    self.execute_next_task()
  File "/Library/Frameworks/Python.framework/Versions/3.12/lib/python3.12/site-packages/locust/user/task.py", line 373, in execute_next_task
    self.execute_task(self._task_queue.popleft())
  File "/Library/Frameworks/Python.framework/Versions/3.12/lib/python3.12/site-packages/locust/user/task.py", line 490, in execute_task
    task(self.user)
  File "/Users/chiragkhanduja/PycharmProjects/Hudle_Load/new_partner.py", line 124, in post_data
    'Code': response_data['data']['code']
            ~~~~~~~~~~~~~~~~~~~~~^^^^^^^^
KeyError: 'code'

[2024-07-23 13:48:05,613] Chirags-Macbook/ERROR/locust.user.task: 'code'
Traceback (most recent call last):
  File "/Library/Frameworks/Python.framework/Versions/3.12/lib/python3.12/site-packages/locust/user/task.py", line 340, in run
    self.execute_next_task()
  File "/Library/Frameworks/Python.framework/Versions/3.12/lib/python3.12/site-packages/locust/user/task.py", line 373, in execute_next_task
    self.execute_task(self._task_queue.popleft())
  File "/Library/Frameworks/Python.framework/Versions/3.12/lib/python3.12/site-packages/locust/user/task.py", line 490, in execute_task
    task(self.user)
  File "/Users/chiragkhanduja/PycharmProjects/Hudle_Load/new_partner.py", line 124, in post_data
    'Code': response_data['data']['code']
            ~~~~~~~~~~~~~~~~~~~~~^^^^^^^^
KeyError: 'code'

[2024-07-23 13:48:05,703] Chirags-Macbook/ERROR/locust.user.task: 'code'
Traceback (most recent call last):
  File "/Library/Frameworks/Python.framework/Versions/3.12/lib/python3.12/site-packages/locust/user/task.py", line 340, in run
    self.execute_next_task()
  File "/Library/Frameworks/Python.framework/Versions/3.12/lib/python3.12/site-packages/locust/user/task.py", line 373, in execute_next_task
    self.execute_task(self._task_queue.popleft())
  File "/Library/Frameworks/Python.framework/Versions/3.12/lib/python3.12/site-packages/locust/user/task.py", line 490, in execute_task
    task(self.user)
  File "/Users/chiragkhanduja/PycharmProjects/Hudle_Load/new_partner.py", line 124, in post_data
    'Code': response_data['data']['code']
            ~~~~~~~~~~~~~~~~~~~~~^^^^^^^^
KeyError: 'code'

[2024-07-23 13:48:06,046] Chirags-Macbook/ERROR/locust.user.task: 'code'
Traceback (most recent call last):
  File "/Library/Frameworks/Python.framework/Versions/3.12/lib/python3.12/site-packages/locust/user/task.py", line 340, in run
    self.execute_next_task()
  File "/Library/Frameworks/Python.framework/Versions/3.12/lib/python3.12/site-packages/locust/user/task.py", line 373, in execute_next_task
    self.execute_task(self._task_queue.popleft())
  File "/Library/Frameworks/Python.framework/Versions/3.12/lib/python3.12/site-packages/locust/user/task.py", line 490, in execute_task
    task(self.user)
  File "/Users/chiragkhanduja/PycharmProjects/Hudle_Load/new_partner.py", line 124, in post_data
    'Code': response_data['data']['code']
            ~~~~~~~~~~~~~~~~~~~~~^^^^^^^^
KeyError: 'code'

[2024-07-23 13:48:06,577] Chirags-Macbook/ERROR/locust.user.task: 'code'
Traceback (most recent call last):
  File "/Library/Frameworks/Python.framework/Versions/3.12/lib/python3.12/site-packages/locust/user/task.py", line 340, in run
    self.execute_next_task()
  File "/Library/Frameworks/Python.framework/Versions/3.12/lib/python3.12/site-packages/locust/user/task.py", line 373, in execute_next_task
    self.execute_task(self._task_queue.popleft())
  File "/Library/Frameworks/Python.framework/Versions/3.12/lib/python3.12/site-packages/locust/user/task.py", line 490, in execute_task
    task(self.user)
  File "/Users/chiragkhanduja/PycharmProjects/Hudle_Load/new_partner.py", line 124, in post_data
    'Code': response_data['data']['code']
            ~~~~~~~~~~~~~~~~~~~~~^^^^^^^^
KeyError: 'code'

[2024-07-23 13:48:06,657] Chirags-Macbook/ERROR/locust.user.task: 'code'
Traceback (most recent call last):
  File "/Library/Frameworks/Python.framework/Versions/3.12/lib/python3.12/site-packages/locust/user/task.py", line 340, in run
    self.execute_next_task()
  File "/Library/Frameworks/Python.framework/Versions/3.12/lib/python3.12/site-packages/locust/user/task.py", line 373, in execute_next_task
    self.execute_task(self._task_queue.popleft())
  File "/Library/Frameworks/Python.framework/Versions/3.12/lib/python3.12/site-packages/locust/user/task.py", line 490, in execute_task
    task(self.user)
  File "/Users/chiragkhanduja/PycharmProjects/Hudle_Load/new_partner.py", line 124, in post_data
    'Code': response_data['data']['code']
            ~~~~~~~~~~~~~~~~~~~~~^^^^^^^^
KeyError: 'code'

[2024-07-23 13:48:07,048] Chirags-Macbook/ERROR/locust.user.task: 'code'
Traceback (most recent call last):
  File "/Library/Frameworks/Python.framework/Versions/3.12/lib/python3.12/site-packages/locust/user/task.py", line 340, in run
    self.execute_next_task()
  File "/Library/Frameworks/Python.framework/Versions/3.12/lib/python3.12/site-packages/locust/user/task.py", line 373, in execute_next_task
    self.execute_task(self._task_queue.popleft())
  File "/Library/Frameworks/Python.framework/Versions/3.12/lib/python3.12/site-packages/locust/user/task.py", line 490, in execute_task
    task(self.user)
  File "/Users/chiragkhanduja/PycharmProjects/Hudle_Load/new_partner.py", line 124, in post_data
    'Code': response_data['data']['code']
            ~~~~~~~~~~~~~~~~~~~~~^^^^^^^^
KeyError: 'code'

[2024-07-23 13:48:07,215] Chirags-Macbook/ERROR/locust.user.task: 'code'
Traceback (most recent call last):
  File "/Library/Frameworks/Python.framework/Versions/3.12/lib/python3.12/site-packages/locust/user/task.py", line 340, in run
    self.execute_next_task()
  File "/Library/Frameworks/Python.framework/Versions/3.12/lib/python3.12/site-packages/locust/user/task.py", line 373, in execute_next_task
    self.execute_task(self._task_queue.popleft())
  File "/Library/Frameworks/Python.framework/Versions/3.12/lib/python3.12/site-packages/locust/user/task.py", line 490, in execute_task
    task(self.user)
  File "/Users/chiragkhanduja/PycharmProjects/Hudle_Load/new_partner.py", line 124, in post_data
    'Code': response_data['data']['code']
            ~~~~~~~~~~~~~~~~~~~~~^^^^^^^^
KeyError: 'code'

[2024-07-23 13:48:07,323] Chirags-Macbook/ERROR/locust.user.task: 'code'
Traceback (most recent call last):
  File "/Library/Frameworks/Python.framework/Versions/3.12/lib/python3.12/site-packages/locust/user/task.py", line 340, in run
    self.execute_next_task()
  File "/Library/Frameworks/Python.framework/Versions/3.12/lib/python3.12/site-packages/locust/user/task.py", line 373, in execute_next_task
    self.execute_task(self._task_queue.popleft())
  File "/Library/Frameworks/Python.framework/Versions/3.12/lib/python3.12/site-packages/locust/user/task.py", line 490, in execute_task
    task(self.user)
  File "/Users/chiragkhanduja/PycharmProjects/Hudle_Load/new_partner.py", line 124, in post_data
    'Code': response_data['data']['code']
            ~~~~~~~~~~~~~~~~~~~~~^^^^^^^^
KeyError: 'code'

[2024-07-23 13:48:07,577] Chirags-Macbook/ERROR/locust.user.task: 'code'
Traceback (most recent call last):
  File "/Library/Frameworks/Python.framework/Versions/3.12/lib/python3.12/site-packages/locust/user/task.py", line 340, in run
    self.execute_next_task()
  File "/Library/Frameworks/Python.framework/Versions/3.12/lib/python3.12/site-packages/locust/user/task.py", line 373, in execute_next_task
    self.execute_task(self._task_queue.popleft())
  File "/Library/Frameworks/Python.framework/Versions/3.12/lib/python3.12/site-packages/locust/user/task.py", line 490, in execute_task
    task(self.user)
  File "/Users/chiragkhanduja/PycharmProjects/Hudle_Load/new_partner.py", line 124, in post_data
    'Code': response_data['data']['code']
            ~~~~~~~~~~~~~~~~~~~~~^^^^^^^^
KeyError: 'code'

[2024-07-23 13:48:07,722] Chirags-Macbook/ERROR/locust.user.task: 'code'
Traceback (most recent call last):
  File "/Library/Frameworks/Python.framework/Versions/3.12/lib/python3.12/site-packages/locust/user/task.py", line 340, in run
    self.execute_next_task()
  File "/Library/Frameworks/Python.framework/Versions/3.12/lib/python3.12/site-packages/locust/user/task.py", line 373, in execute_next_task
    self.execute_task(self._task_queue.popleft())
  File "/Library/Frameworks/Python.framework/Versions/3.12/lib/python3.12/site-packages/locust/user/task.py", line 490, in execute_task
    task(self.user)
  File "/Users/chiragkhanduja/PycharmProjects/Hudle_Load/new_partner.py", line 124, in post_data
    'Code': response_data['data']['code']
            ~~~~~~~~~~~~~~~~~~~~~^^^^^^^^
KeyError: 'code'

[2024-07-23 13:48:07,845] Chirags-Macbook/ERROR/locust.user.task: 'data'
Traceback (most recent call last):
  File "/Library/Frameworks/Python.framework/Versions/3.12/lib/python3.12/site-packages/locust/user/task.py", line 340, in run
    self.execute_next_task()
  File "/Library/Frameworks/Python.framework/Versions/3.12/lib/python3.12/site-packages/locust/user/task.py", line 373, in execute_next_task
    self.execute_task(self._task_queue.popleft())
  File "/Library/Frameworks/Python.framework/Versions/3.12/lib/python3.12/site-packages/locust/user/task.py", line 490, in execute_task
    task(self.user)
  File "/Users/chiragkhanduja/PycharmProjects/Hudle_Load/new_partner.py", line 121, in post_data
    'ID': response_data['data']['id'],  # Add this line
          ~~~~~~~~~~~~~^^^^^^^^
KeyError: 'data'

[2024-07-23 13:48:08,161] Chirags-Macbook/INFO/locust.main: writing html report to file: repo.html
[2024-07-23 13:48:08,252] Chirags-Macbook/ERROR/root: Uncaught exception in event handler: 
Traceback (most recent call last):
  File "/Library/Frameworks/Python.framework/Versions/3.12/lib/python3.12/site-packages/locust/event.py", line 47, in fire
    handler(**kwargs)
  File "/Users/chiragkhanduja/PycharmProjects/Hudle_Load/new_partner.py", line 157, in on_quitting
    save_to_excel(df, 'response.xlsx')
  File "/Users/chiragkhanduja/PycharmProjects/Hudle_Load/new_partner.py", line 146, in save_to_excel
    format = workbook.add_format({'text_wrap': True, 'valign': 'top', 'border': 1})
             ^^^^^^^^^^^^^^^^^^^
AttributeError: 'Workbook' object has no attribute 'add_format'

[2024-07-23 13:48:08,252] Chirags-Macbook/INFO/locust.main: Shutting down (exit code 1)
[2024-07-23 13:49:16,814] Chirags-Macbook/INFO/locust.main: Run time limit set to 10 seconds
[2024-07-23 13:49:16,815] Chirags-Macbook/INFO/locust.main: Starting Locust 2.28.0
[2024-07-23 13:49:16,815] Chirags-Macbook/INFO/locust.runners: Ramping to 100 users at a rate of 1.00 per second
[2024-07-23 13:49:26,296] Chirags-Macbook/INFO/locust.main: --run-time limit reached, shutting down
[2024-07-23 13:49:26,367] Chirags-Macbook/INFO/locust.main: writing html report to file: repo.html
[2024-07-23 13:49:26,441] Chirags-Macbook/ERROR/root: Uncaught exception in event handler: 
Traceback (most recent call last):
  File "/Library/Frameworks/Python.framework/Versions/3.12/lib/python3.12/site-packages/locust/event.py", line 47, in fire
    handler(**kwargs)
  File "/Users/chiragkhanduja/PycharmProjects/Hudle_Load/new_partner.py", line 157, in on_quitting
    save_to_excel(df, 'response.xlsx')
  File "/Users/chiragkhanduja/PycharmProjects/Hudle_Load/new_partner.py", line 146, in save_to_excel
    format = workbook.add_format({'text_wrap': True, 'valign': 'top', 'border': 1})
             ^^^^^^^^^^^^^^^^^^^
AttributeError: 'Workbook' object has no attribute 'add_format'

[2024-07-23 13:49:26,441] Chirags-Macbook/INFO/locust.main: Shutting down (exit code 2)
[2024-07-23 13:50:58,639] Chirags-Macbook/INFO/locust.main: Run time limit set to 10 seconds
[2024-07-23 13:50:58,639] Chirags-Macbook/INFO/locust.main: Starting Locust 2.28.0
[2024-07-23 13:50:58,640] Chirags-Macbook/INFO/locust.runners: Ramping to 100 users at a rate of 1.00 per second
[2024-07-23 13:51:02,820] Chirags-Macbook/ERROR/locust.user.task: 'data'
Traceback (most recent call last):
  File "/Library/Frameworks/Python.framework/Versions/3.12/lib/python3.12/site-packages/locust/user/task.py", line 340, in run
    self.execute_next_task()
  File "/Library/Frameworks/Python.framework/Versions/3.12/lib/python3.12/site-packages/locust/user/task.py", line 373, in execute_next_task
    self.execute_task(self._task_queue.popleft())
  File "/Library/Frameworks/Python.framework/Versions/3.12/lib/python3.12/site-packages/locust/user/task.py", line 490, in execute_task
    task(self.user)
  File "/Users/chiragkhanduja/PycharmProjects/Hudle_Load/new_partner.py", line 122, in post_data
    'ID': response_data['data']['id'],  # Add this line
          ~~~~~~~~~~~~~^^^^^^^^
KeyError: 'data'

[2024-07-23 13:51:08,167] Chirags-Macbook/INFO/locust.main: --run-time limit reached, shutting down
[2024-07-23 13:51:08,243] Chirags-Macbook/INFO/locust.main: writing html report to file: repo.html
[2024-07-23 13:51:08,325] Chirags-Macbook/ERROR/root: Uncaught exception in event handler: 
Traceback (most recent call last):
  File "/Library/Frameworks/Python.framework/Versions/3.12/lib/python3.12/site-packages/locust/event.py", line 47, in fire
    handler(**kwargs)
  File "/Users/chiragkhanduja/PycharmProjects/Hudle_Load/new_partner.py", line 159, in on_quitting
    save_to_excel(df, f'response_{timestamp}.xlsx')
  File "/Users/chiragkhanduja/PycharmProjects/Hudle_Load/new_partner.py", line 147, in save_to_excel
    format = workbook.add_format({'text_wrap': True, 'valign': 'top', 'border': 1})
             ^^^^^^^^^^^^^^^^^^^
AttributeError: 'Workbook' object has no attribute 'add_format'

[2024-07-23 13:51:08,327] Chirags-Macbook/INFO/locust.main: Shutting down (exit code 1)
